Workbook

Sheet Parameter
A1: Payment Type-1 | B1: Payment Type-2 | C1: Payment Type-3 | D1: Review | E1: Final | H1: Pendapatan Denda | J1: % Pengali | K1: Grup Denda | N1: PaymentType | O1: Note | Q1: PaymentType
A2: T-ATM | B2: T-ATM | C2: Non Pick UP | E2: Non Pick UP | H2: 0 | I2: 500000 | J2: 0.05 | K2: 500,000 < | N2: ALFAMRT | O2: 0 | Q2: CASH
A3: T-Pick Up (ARO) | B3: T-PICK UP (ARO) | C3: Pick UP | E3: Pick UP | H3: 500000 | I3: 1000000 | J3: 0.075 | K3: 1,000,000 < | N3: ARJAS | O3: 0 | Q3: PICKUP
A4: T-Kas | B4: T-KAS | C4: Cashier | D4: WINPAY | E4: WINPAY | H4: 1000000 | I4: 2000000 | J4: 0.1 | K4: 2,000,000 < | N4: BANK | O4: 0 | Q4: PREPAID
A5: T-Bank | B5: T-BANK | C5: Non Pick UP | E5: Non Pick UP | H5: 2000000 | I5: 1000000000 | J5: 0.15 | K5: 2,000,000 > | N5: BLIBLI | O5: 0 | Q5: WINPAY
A6: T-ARTA JASA | B6: T-ARTA JASA | C6: Non Pick UP | D6: Online Payment | E6: Payment Online | N6: BUKALAPAK | O6: 0
A7: T-Dealer | B7: T-DEALER | C7: Non Pick UP | E7: Non Pick UP | H7: PIC | I7: Grup PIC | N7: CASH | O7: 1
A8: T-DCS | B8: T-DCS | C8: Non Pick UP | E8: Non Pick UP | H8: ARO 1 | I8: 01. STAFF | N8: DANA | O8: 0
A9: T-EDC | B9: T-EDC | C9: Non Pick UP | E9: Non Pick UP | H9: ARO 2 | I9: 01. STAFF | N9: GOJEK | O9: 0
A10: T-Titipan | B10: T-TITIPAN | C10: Non Pick UP | E10: Non Pick UP | H10: REM OFF | I10: 01. STAFF | N10: INDOMRT | O10: 0
A11: T-Kas SYB | B11: T-KAS SYB | C11: Non Pick UP | E11: Non Pick UP | H11: AR COORD | I11: 02. COORD | N11: LINKAJA | O11: 0
A12: T-PDC | B12: T-PDC | C12: Non Pick UP | E12: Non Pick UP | H12: REM COORD | I12: 02. COORD | N12: PICKUP | O12: 1
A13: T-INDOMARET | B13: T-INDOMARET | C13: Payment Online | D13: Online Payment | E13: Payment Online | H13: AR HEAD | I13: 03. HEAD | N13: PMTA | O13: 0
A14: T-Alfamart | B14: T-ALFAMART | C14: Payment Online | D14: Online Payment | E14: Payment Online | H14: PSO HEAD | I14: 03. HEAD | N14: PREPAID | O14: 1
A15: Dealer | B15: T-DEALER | C15: Non Pick UP | E15: Non Pick UP | H15: REM HEAD | I15: 03. HEAD | N15: SHOPEE | O15: 0
A16: DCS | B16: T-DCS | C16: Non Pick UP | E16: Non Pick UP | H16: REC HEAD | I16: 04. RECOVERY | N16: SYBMANDIRI | O16: 0
A17: Pick Up (ARO) | B17: T-PICK UP (ARO) | C17: Pick UP | E17: Pick UP | H17: REC COORD | I17: 04. RECOVERY | N17: TOKOPEDIA | O17: 0
A18: Titipan | B18: T-TITIPAN | C18: Non Pick UP | E18: Non Pick UP | H18: ADD INS | I18: 05. ADD INS | N18: WINPAY | O18: 1
A19: Kas | B19: T-KAS | C19: Cashier | D19: WINPAY | E19: WINPAY | H19: REWARD ENTRANT | I19: 05. ADD INS
A20: Alfamrt | B20: T-ALFAMART | C20: Payment Online | D20: Online Payment | E20: Payment Online | H20: OUTSOURCE | I20: 07. OUTSOURCE
A21: Artha Jasa | B21: T-ARTA JASA | C21: Non Pick UP | D21: Online Payment | E21: Payment Online
A22: Bank | B22: T-BANK | C22: Non Pick UP | E22: Non Pick UP
A23: Cash | B23: T-KAS | C23: Cashier | D23: WINPAY | E23: WINPAY
A24: INDOMRT | B24: T-INDOMARET | C24: Payment Online | D24: Online Payment | E24: Payment Online
A25: PDC | B25: T-PDC | C25: Non Pick UP | E25: Non Pick UP
A26: Permata | B26: T-BANK | C26: Non Pick UP | D26: Online Payment | E26: Payment Online
A27: Pickup | B27: T-PICK UP (ARO) | C27: Pick UP | E27: Pick UP
A28: Suspend | B28: T-TITIPAN | C28: Non Pick UP | E28: Non Pick UP
A29: PREPAID | B29: PREPAID | C29: WINPAY | E29: WINPAY
A30: ARJAS | B30: T-ARTA JASA | C30: Non Pick UP | D30: Online Payment | E30: Payment Online
A31: ADIKP | B31: T-ARTA JASA | C31: Non Pick UP | E31: Non Pick UP
A32: PMTA | B32: T-PMTA | C32: Non Pick UP | D32: Online Payment | E32: Payment Online
A33: TOKOPEDIA | B33: T-TOKOPEDIA | C33: Payment Online | D33: Online Payment | E33: Payment Online
A34: GOJEK | B34: T-GOJEK | C34: Payment Online | D34: Online Payment | E34: Payment Online
A35: BUKALAPAK | B35: T-BUKALAPAK | C35: Payment Online | D35: Online Payment | E35: Payment Online
A36: SHOPEE | B36: T-SHOPEE | C36: Payment Online | D36: Online Payment | E36: Payment Online
A37: LINKAJA | B37: T-LINKAJA | C37: Payment Online | D37: Online Payment | E37: Payment Online
A38: DANA | B38: T-DANA | C38: Payment Online | D38: Online Payment | E38: Payment Online
A39: BLIBLI | B39: T-BLIBLI | C39: Payment Online | D39: Online Payment | E39: Payment Online
A40: SYBMANDIRI | B40: T-BANK | C40: Non Pick UP | D40: Online Payment | E40: Payment Online
...

Sheet New KC
A1: BranchID | B1: BranchName | C1: BranchName- | D1: New Area | E1: Code | F1: New Area_Old | G1: BranchName_Old | H1: New Area_New | I1: BranchName_New | J1: Status | K1: Unit | M1: -10000 | N1: 0 | O1: 00.Not Ovd | P1: 00.Not OD | Q1: ARO
A2: 1001 | B2: BANJARMASIN | C2: BANJARMASIN | D2: 08. Kalselteng | E2: 2W | F2: 05. Kalimantan | G2: BANJARMASIN | H2: 05. Kalimantan | I2: BANJARMASIN | J2: BRANCH | K2: 1 | M2: 1 | N2: 30 | O2: 01.1-30 | P2: 01.1-30 | Q2: ARO
A3: 1002 | B3: MAKASAR | C3: MAKASAR | D3: 09. SulbagSel | E3: 2W | F3: 06. Sulawesi | G3: MAKASSAR | H3: 06. Sulawesi | I3: MAKASSAR | J3: BRANCH | K3: 1 | M3: 31 | N3: 60 | O3: 02.31-60 | P3: 02.31-60 | Q3: PSO
A4: 1003 | B4: BALIKPAPAN | C4: BALIKPAPAN | D4: 07. KalTimBar | E4: 2W | F4: 05. Kalimantan | G4: BALIKPAPAN | H4: 05. Kalimantan | I4: BALIKPAPAN | J4: BRANCH | K4: 1 | M4: 61 | N4: 90 | O4: 03.61-90 | P4: 03.61-90 | Q4: PSO
A5: 1004 | B5: SAMARINDA | C5: SAMARINDA | D5: 07. KalTimBar | E5: 2W | F5: 05. Kalimantan | G5: SAMARINDA | H5: 05. Kalimantan | I5: SAMARINDA | J5: BRANCH | K5: 1 | M5: 91 | N5: 120 | O5: 04.91-120 | P5: 04.91-120 | Q5: REMOFF
A6: 1005 | B6: BOGOR | C6: BOGOR | D6: 02. Jabotabek | E6: 2W | F6: 01. Jabodetabekser | G6: BOGOR | H6: 01. Jabodetabekser | I6: BOGOR | J6: BRANCH | K6: 1 | M6: 121 | N6: 150 | O6: 05.121-150 | P6: 05.121-150 | Q6: REMOFF
A7: 1006 | B7: BEKASI | C7: BEKASI | D7: 02. Jabotabek | E7: 2W | F7: 01. Jabodetabekser | G7: BEKASI | H7: 01. Jabodetabekser | I7: BEKASI | J7: BRANCH | K7: 1 | M7: 151 | N7: 180 | O7: 06.151-180 | P7: 06.151-180 | Q7: REMOFF
A8: 1007 | B8: KEDIRI | C8: KEDIRI | D8: 05. JatimSel | E8: 2W | F8: 04. Jawa Timur | G8: KEDIRI | H8: 04. Jawa Timur | I8: KEDIRI | J8: BRANCH | K8: 1 | M8: 181 | N8: 10000000 | O8: 07.>180 | P8: 07.>180 | Q8: PC
A9: 1008 | B9: KARAWANG | C9: KARAWANG | D9: 01. Jabar | E9: 2W | F9: 02. Jawa Barat | G9: KARAWANG | H9: 02. Jawa Barat | I9: KARAWANG | J9: BRANCH | K9: 1
A10: 1009 | B10: MADIUN | C10: MADIUN | D10: 06. JatimUt | E10: 2W | F10: 04. Jawa Timur | G10: KEDIRI | H10: 04. Jawa Timur | I10: KEDIRI | J10: DCSM MIX | K10: 1
A11: 1010 | B11: MEDAN | C11: MEDAN | D11: 13. SumbagUt | E11: 2W | F11: 08. Sumbaguteng | G11: MEDAN | H11: 08. Sumbaguteng | I11: MEDAN | J11: BRANCH | K11: 1
A12: 1011 | B12: KELAPA GADING | C12: KELAPA GADING | D12: 02. Jabotabek | E12: 2W | F12: 01. Jabodetabekser | G12: KELAPA GADING / SUNTER | H12: 01. Jabodetabekser | I12: SUNTER | J12: BRANCH | K12: 1
A13: 1012 | B13: BANDUNG | C13: BANDUNG | D13: 01. Jabar | E13: 2W | F13: 02. Jawa Barat | G13: BANDUNG | H13: 02. Jawa Barat | I13: BANDUNG | J13: BRANCH | K13: 1
A14: 1013 | B14: YOGYA | C14: YOGYA | D14: 03. JatengSel | E14: 2W | F14: 03. Jawa Tengah | G14: YOGYAKARTA | H14: 03. Jawa Tengah | I14: YOGYAKARTA | J14: BRANCH | K14: 1
A15: 1014 | B15: SOLO | C15: SOLO | D15: 03. JatengSel | E15: 2W | F15: 03. Jawa Tengah | G15: SOLO | H15: 03. Jawa Tengah | I15: SOLO | J15: BRANCH | K15: 1
A16: 1015 | B16: SEMARANG | C16: SEMARANG | D16: 04. Jatengut | E16: 2W | F16: 03. Jawa Tengah | G16: SEMARANG | H16: 03. Jawa Tengah | I16: SEMARANG | J16: BRANCH | K16: 1
A17: 1016 | B17: SURABAYA | C17: SURABAYA | D17: 06. JatimUt | E17: 2W | F17: 04. Jawa Timur | G17: SURABAYA | H17: 04. Jawa Timur | I17: SURABAYA | J17: BRANCH | K17: 1
A18: 1017 | B18: MALANG | C18: MALANG | D18: 05. JatimSel | E18: 2W | F18: 04. Jawa Timur | G18: MALANG | H18: 04. Jawa Timur | I18: MALANG | J18: BRANCH | K18: 1
A19: 1018 | B19: SIDOARJO | C19: SIDOARJO | D19: 06. JatimUt | E19: 2W | F19: 04. Jawa Timur | G19: SURABAYA | H19: 04. Jawa Timur | I19: SURABAYA | J19: DCSM MIX | K19: 1
A20: 1019 | B20: GRESIK | C20: GRESIK | D20: 06. JatimUt | E20: 2W | F20: 04. Jawa Timur | G20: GRESIK | H20: 04. Jawa Timur | I20: GRESIK | J20: BRANCH | K20: 1
... A84: 1082 | B84: UJUNG BATU | C84: PEKAN BARU | D84: 12. SumbagTeng | E84: 2W | F84: 08. Sumbaguteng | G84: PEKANBARU | H84: 08. Sumbaguteng | I84: PEKANBARU | J84: BRANCH | K84: 1
A85: 1083 | B85: LUBUK LINGGAU | C85: PALEMBANG | D85: 11. SumbagSel | E85: 2W | F85: 07. Sumbagsel | G85: BENGKULU | H85: 07. Sumbagsel | I85: PALEMBANG | J85: BRANCH | K85: 1 | L85: PALEMBANG 1-4
A86: 1086 | B86: MAKASSAR 2 | C86: MAKASAR | D86: 09. SulbagSel | E86: 2W | F86: 06. Sulawesi | G86: MAKASSAR | H86: 06. Sulawesi | I86: MAKASSAR | J86: BRANCH | K86: 1
A87: 1087 | B87: SAMPIT | C87: SAMPIT | D87: 08. Kalselteng | E87: 2W | F87: 05. Kalimantan | G87: SAMPIT | H87: 05. Kalimantan | I87: SAMPIT | J87: BRANCH | K87: 1
A88: 1088 | B88: BANDAR JAYA | C88: BANDAR JAYA | D88: 11. SumbagSel | E88: 2W | F88: 07. Sumbagsel | G88: BANDAR LAMPUNG | H88: 07. Sumbagsel | I88: BANDAR LAMPUNG | J88: DCSM MIX | K88: 1
A89: 1089 | B89: KUPANG | C89: KUPANG | D89: 14. IBT | E89: 2W | F89: 09. IBT | G89: KUPANG | H89: 09. IBT | I89: KUPANG | J89: BRANCH | K89: 1
A90: 1090 | B90: BUKITTINGGI | C90: PADANG | D90: 12. SumbagTeng | E90: 2W | F90: 08. Sumbaguteng | G90: PADANG | H90: 08. Sumbaguteng | I90: PADANG | J90: BRANCH | K90: 1
A91: 1094 | B91: MEDAN 2 | C91: MEDAN | D91: 13. SumbagUt | E91: 2W | F91: 08. Sumbaguteng | G91: MEDAN | H91: 08. Sumbaguteng | I91: MEDAN | J91: BRANCH | K91: 1
A92: 1095 | B92: MEDAN 3 | C92: MEDAN | D92: 13. SumbagUt | E92: 2W | F92: 08. Sumbaguteng | G92: MEDAN | H92: 08. Sumbaguteng | I92: MEDAN | J92: BRANCH | K92: 1
A93: 1301 | B93: BANJARMASIN Syariah | C93: BANJARMASIN | D93: 08. Kalselteng | E93: 2W | F93: 05. Kalimantan | G93: BANJARMASIN | H93: 05. Kalimantan | I93: BANJARMASIN | J93: BRANCH | K93: 1
A94: 1302 | B94: MAKASAR Syariah | C94: MAKASAR | D94: 09. SulbagSel | E94: 2W | F94: 06. Sulawesi | G94: MAKASSAR | H94: 06. Sulawesi | I94: MAKASSAR | J94: BRANCH | K94: 1
A95: 1303 | B95: BALIKPAPAN Syariah | C95: BALIKPAPAN | D95: 07. KalTimBar | E95: 2W | F95: 05. Kalimantan | G95: BALIKPAPAN | H95: 05. Kalimantan | I95: BALIKPAPAN | J95: BRANCH | K95: 1
A96: 1304 | B96: SAMARINDA Syariah | C96: SAMARINDA | D96: 07. KalTimBar | E96: 2W | F96: 05. Kalimantan | G96: SAMARINDA | H96: 05. Kalimantan | I96: SAMARINDA | J96: BRANCH | K96: 1
A97: 1305 | B97: BOGOR Syariah | C97: BOGOR | D97: 02. Jabotabek | E97: 2W | F97: 01. Jabodetabekser | G97: BOGOR | H97: 01. Jabodetabekser | I97: BOGOR | J97: BRANCH | K97: 1
... A226: 1805 | B226: OBM - TERNATE | C226: OBM - TERNATE | D226: 15. OBM | E226: OBM | F226: 10. OBM | G226: OBM - TERNATE | H226: 06. Sulawesi | I226: TERNATE | J226: BRANCH | K226: 1

Sheet DB N-1
A1: AREA | B1: BRANCHID | C1: CABANG_MERGER | D1: CABANG | E1: BUSINESS_UNIT | F1: NOMOR_KONTRAK | G1: NAMA_DEBITUR | H1: GO_LIVE_DATE | I1: TANGGAL_BAYAR_ANGS_TERAKHIR | J1: MERK_KENDARAAN | K1: TYPE_KENDARAAN | L1: TAHUN_KENDARAAN | M1: NO_HP_1 | N1: NO_HP_2 | O1: RESIDENCE_ADDRESS | P1: LEGAL_ADDRESS | Q1: JOB_ADDRESS | R1: EMERGENCY_ADDRESS | S1: OS_PRINCIPAL_AMT | T1: OS_LC_INST_AMT | U1: OS_CHARGE_RCV_AMT | V1: TOTAL_AMOUNT_TO_BE_PAID_1 | W1: PREPAID | X1: TOTAL_KEWAJIBAN | Y1: CONTRACT_STAT | Z1: TOTAL_AMOUNT_TO_BE_PAID_2 | AA1: TGL_PEMBAYARAN | AB1: AMOUNT_PEMBAYARAN_1 | AC1: AMOUNT_PEMBAYARAN | AD1: WOP | AE1: AMOUNT_WOP | AF1: WAIVE_AMOUNT_1 | AG1: REVERSAL | AH1: TGL_RRD | AI1: STATUS_BPKB | AJ1: WAIVE_AMOUNT_2 | AK1: WAIVE_PCTG_MIN_TOTAL_AMOUNT_TO_BE_PAID | AL1: WAIVE_PCTG_MIN_TOTAL_KEWAJIBAN | AM1: VERIFIKASI_MIN_TOTAL_AMOUNT_TO_BE_PAID | AN1: VERIFIKASI_MIN_TOTAL_KEWAJIBAN | AO1: New Area | AP1: New Cabang | AQ1: Tgl ( TGL_PEMBAYARAN ) | AR1: Periode ( TGL_PEMBAYARAN ) | AS1: Periode ( TANGGAL_BAYAR_ANGS_TERAKHIR ) | AT1: Flag Alda / Aktif | AU1: Cek Alda / Aktif | AV1: Unit Pakai As of | AW1: Unit Pakai As of
A2: IBT | B2: 1503 | C2: Denpasar | D2: DENPASAR - MBL | E2: 4W | F2: 1503130000206 | G2: I NYOMAN SUDI ASRINTAWA | H2: 41354 | I2: 43220 | J2: SUZUKI | K2: ERTIGA | L2: 2013 | M2: 081338614050 | O2: BANJAR PERANCAK RT - /RW -, PERANCAK, NEGARA, JEMBRANA, 82251 | P2: BANJAR PERANCAK RT - /RW -, PERANCAK , JEMBRANA , JEMBRANA, 82251 | S2: 0 | T2: 17658936 | U2: 0 | V2: 17658936 | W2: 0 | X2: 17658936 | Y2: EXP | Z2: 0 | AA2: 46167 | AB2: 13500000 | AC2: 13500000 | AD2: WINPAY | AE2: 0 | AF2: 4158936.4 | AG2: 0 | AH2: 46168 | AI2: Release | AJ2: 4158936.4 | AK2: 0.24 | AL2: 0.24 | AM2: 0 | AN2: 0 | AO2: 09. IBT | AP2: DENPASAR | AQ2: 25 | AR2: 26-05 | AS2: 18-04 | AT2: ALDA | AU2: FALSE | AV2: =IF(AQ2<=DAY(TODAY()),1,0) -> 0 | AW2: =IF(AQ2=DAY(TODAY()),1,0) -> 0
A3: Sumatera | B3: 1520 | C3: Pekan Baru | D3: PEKANBARU - MBL | E3: 4W | F3: 1520160000056 | G3: HENDRI YANTES | H3: 42590 | I3: 44067 | J3: SUZUKI | K3: CARRY PU 1.5 WD | L3: 2016 | M3: 085271509719 | O3: JL SWAKARYA NO 20 RT 001 /RW 026, TUAH KARYA, TAMPAN, PEKANBARU, 28291 | P3: JL MELATI PERUM PONDOK MAYANG BLOK B-16 RT 003 /RW 016, SAIL, TENAYAN RAYA, PEKANBARU, 28285 | Q3: JL SWAKARYA NO 20 RT 001 /RW 026, TUAH KARYA, TAMPAN, PEKANBARU, 28291 | S3: 0 | T3: 5894680 | U3: 0 | V3: 5894680 | W3: 1000 | X3: 5893680 | Y3: RRD | Z3: 0 | AA3: 46171 | AB3: 4715000 | AC3: 4715000 | AD3: WINPAY | AE3: 0 | AF3: 1178736 | AG3: 0 | AH3: 46171 | AI3: On Hand | AJ3: 1178736 | AK3: 0.2 | AL3: 0.2 | AM3: 944 | AN3: -56 | AO3: 08. Sumbaguteng | AP3: PEKANBARU | AQ3: 29 | AR3: 26-05 | AS3: 20-08 | AT3: ALDA | AU3: FALSE | AV3: =IF(AQ3<=DAY(TODAY()),1,0) -> 0 | AW3: =IF(AQ3=DAY(TODAY()),1,0) -> 0
A4: Jateng | B4: 1524 | C4: Tegal | D4: TEGAL - MBL | E4: 4W | F4: 1524170000173 | G4: AKHMAD YASIN | H4: 43099 | I4: 44874 | J4: SUZUKI | K4: CARRY PU 1.5 | L4: 2017 | M4: 082199712299 | N4: 085226186063 | O4: GROBOG KULON RT 002 /RW 002, GROBOG KULON, PANGKAH, TEGAL, 52471 | P4: GROBOG KULON RT 002 /RW 002, GROBOG KULON, PANGKAH, TEGAL, 52471 | Q4: GROBOG KULON RT 002 /RW 002, GROBOG KULON, PANGKAH, TEGAL, 52471 | S4: 0 | T4: 17168000 | U4: 10000 | V4: 17178000 | W4: 0 | X4: 17178000 | Y4: EXP | Z4: 0 | AA4: 46146 | AB4: 12100000 | AC4: 12100000 | AD4: BANK | AE4: 0 | AF4: 5078000 | AG4: 0 | AH4: 46146 | AI4: Release | AJ4: 5078000 | AK4: 0.3 | AL4: 0.3 | AM4: 0 | AN4: 0 | AO4: 03. Jawa Tengah | AP4: TEGAL | AQ4: 4 | AR4: 26-05 | AS4: 22-11 | AT4: ALDA | AU4: FALSE | AV4: =IF(AQ4<=DAY(TODAY()),1,0) -> 1 | AW4: =IF(AQ4=DAY(TODAY()),1,0) -> 0
A5: Jabodetabekser | B5: 1507 | C5: Tangerang | D5: TANGERANG - MBL | E5: 4W | F5: 1507180001362 | G5: SAPARI | H5: 43404 | I5: 44923 | J5: SUZUKI | K5: CARRY PU 1.5 | L5: 2018 | M5: 082310581011 | O5: KP. PABUARAN RT 001 /RW 004, CIKANDE, CIKANDE, SERANG, 42186 | P5: KP. PABUARAN RT 001 /RW 004, CIKANDE, CIKANDE, SERANG, 42186 | Q5: GRIYA ASRI CENDANA A1/07 RT 000 /RW 000, CIKANDE, CIKANDE, SERANG, 42186 | S5: 0 | T5: 8678590 | U5: 0 | V5: 8678590 | W5: 0 | X5: 8678590 | Y5: EXP | Z5: 0 | AA5: 46157 | AB5: 6943000 | AC5: 6943000 | AD5: WINPAY | AE5: 0 | AF5: 1735590 | AG5: 0 | AH5: 46160 | AI5: Release | AJ5: 1735590 | AK5: 0.2 | AL5: 0.2 | AM5: 0 | AN5: 0 | AO5: 01. Jabodetabekser | AP5: TANGERANG | AQ5: 15 | AR5: 26-05 | AS5: 22-12 | AT5: ALDA | AU5: FALSE | AV5: =IF(AQ5<=DAY(TODAY()),1,0) -> 0 | AW5: =IF(AQ5=DAY(TODAY()),1,0) -> 0
A6: Sulawesi | B6: 1541 | C6: Kendari | D6: KENDARI - MBL | E6: 4W | F6: 1541190000141 | G6: DEDDY JALAL S PD | H6: 43676 | I6: 45114 | J6: SUZUKI | K6: CARRY PU 1.5 | L6: 2019 | M6: 085130333379 | O6: DESA LANGGEA RT 00 /RW 00, LANGGEA, RANOMEETO, KONAWE SELATAN, 93871 | P6: DESA LANGGEA RT 00 /RW 00, LANGGEA, RANOMEETO, KONAWE SELATAN, 93871 | Q6: SMPN 29 KONAWE SELATAN RT 00 /RW 00, LAMERURU (LAMEURU), RANOMEETO BARAT, KONAWE SELATAN, 93871 | S6: 0 | T6: 2380195 | U6: 0 | V6: 2380195 | W6: 0 | X6: 2380195 | Y6: EXP | Z6: 0 | AA6: 46158 | AB6: 2380195 | AC6: 2380195 | AD6: WINPAY | AE6: 0 | AF6: 0 | AG6: 0 | AH6: 46160 | AI6: Release | AK6: 0 | AL6: 0 | AM6: 0 | AN6: 0 | AO6: 06. Sulawesi | AP6: KENDARI | AQ6: 16 | AR6: 26-05 | AS6: 23-07 | AT6: ALDA | AU6: FALSE | AV6: =IF(AQ6<=DAY(TODAY()),1,0) -> 0 | AW6: =IF(AQ6=DAY(TODAY()),1,0) -> 0
A7: Jabodetabekser | B7: 1518 | C7: Dewi Sartika | D7: DEWI SARTIKA - MBL | E7: 4W | F7: 1518190000630 | G7: SYUHYAR EFENDI | H7: 43838 | I7: 45329 | J7: SUZUKI | K7: CARRY PU 1.5 | L7: 2019 | M7: 081384719872 | O7: VILLA PERTIWI BLOK F-6 NO 17 RT 004 /RW 013, SUKAMAJU, CILODONG, DEPOK, 16410 | P7: VILLA PERTIWI BLOK F-6 NO 17 RT 004 /RW 013, SUKAMAJU, CILODONG, DEPOK, 16410 | Q7: VILLA PERTIWI BLOK F-16 NO.17 RT 004 /RW 013, SUKAMAJU, CILODONG, DEPOK, 16410 | S7: 0 | T7: 4461250 | U7: 0 | V7: 4461250 | W7: 0 | X7: 4461250 | Y7: EXP | Z7: 0 | AA7: 46153 | AB7: 4462000 | AC7: 4462000 | AD7: WINPAY | AE7: 0 | AF7: 0 | AG7: 0 | AH7: 46153 | AI7: Release | AK7: 0 | AL7: 0 | AM7: -750 | AN7: -750 | AO7: 01. Jabodetabekser | AP7: DEWI SARTIKA | AQ7: 11 | AR7: 26-05 | AS7: 24-02 | AT7: ALDA | AU7: FALSE | AV7: =IF(AQ7<=DAY(TODAY()),1,0) -> 0 | AW7: =IF(AQ7=DAY(TODAY()),1,0) -> 0
A8: Sumatera | B8: 1520 | C8: Pekan Baru | D8: PEKANBARU - MBL | E8: 4W | F8: 1520200000475 | G8: SANTI ANGGREINI | H8: 44062 | I8: 45525 | J8: SUZUKI | K8: CARRY PU 1.5 | L8: 2020 | M8: 081361290957 | O8: DUSUN II SUKA MAKMUR RT 002 /RW 002, KEPAU JAYA, SIAK HULU, KAMPAR, 28452 | P8: DUSUN II SUKA MAKMUR RT 002 /RW 002, KEPAU JAYA, SIAK HULU, KAMPAR, 28452 | Q8: KEPAU JAYA RT 000 /RW 000, KEPAU JAYA, SIAK HULU, KAMPAR, 28452 | S8: 0 | T8: 1754200 | U8: 0 | V8: 1754200 | W8: 0 | X8: 1754200 | Y8: EXP | Z8: 0 | AA8: 46160 | AB8: 1755000 | AC8: 1755000 | AD8: WINPAY | AE8: 0 | AF8: 0 | AG8: 0 | AH8: 46160 | AI8: Release | AK8: 0 | AL8: 0 | AM8: -800 | AN8: -800 | AO8: 08. Sumbaguteng | AP8: PEKANBARU | AQ8: 18 | AR8: 26-05 | AS8: 24-08 | AT8: ALDA | AU8: FALSE | AV8: =IF(AQ8<=DAY(TODAY()),1,0) -> 0 | AW8: =IF(AQ8=DAY(TODAY()),1,0) -> 0
A9: Sulawesi | B9: 1514 | C9: Makassar | D9: MAKASSAR - MBL | E9: 4W | F9: 1514210000148 | G9: M RADIMAN | H9: 44358 | I9: 45548 | J9: SUZUKI | K9: ERTIGA | L9: 2021 | M9: 081241325566 | N9: 085343877727 | O9: JL KANDEA POROS KANAL MAKASSAR RT 000 /RW 000, BUNGA EJA BERU, TALLO, MAKASSAR, 90211 | P9: JL. KUBIS NO.48 RT 001 /RW 004, WAJO BARU, BONTOALA, MAKASSAR, 90151 | Q9: JL KUBIS NO 48 RT 001 /RW 004, WAJO BARU, BONTOALA, MAKASSAR, 90151 | S9: 0 | T9: 45297127 | U9: 0 | V9: 45297127 | W9: 0 | X9: 45297127 | Y9: ICP | Z9: 45297127 | AA9: 46163 | AB9: 0 | AC9: 0 | AD9: WINPAY | AE9: 0 | AF9: 0 | AG9: 0 | AI9: On Hand | AK9: 0 | AL9: 0 | AM9: 45272127 | AN9: 45272127 | AO9: 06. Sulawesi | AP9: MAKASSAR | AQ9: 21 | AR9: 26-05 | AS9: 24-09 | AT9: ALDA | AU9: FALSE | AV9: =IF(AQ9<=DAY(TODAY()),1,0) -> 0 | AW9: =IF(AQ9=DAY(TODAY()),1,0) -> 0
A10: Sumatera | B10: 1520 | C10: Pekan Baru | D10: PEKANBARU - MBL | E10: 4W | F10: 1520200000605 | G10: MUSARYADI | H10: 44125 | I10: 45626 | J10: SUZUKI | K10: CARRY PU 1.5 | L10: 2020 | M10: 085272700736 | O10: JL.DATUK ANGKASA RT 006 /RW 003, ANGKASA, BANDAR PETALANGAN, PELALAWAN, 28384 | P10: JL.DATUK ANGKASA RT 006 /RW 003, ANGKASA, BANDAR PETALANGAN, PELALAWAN, 28384 | Q10: DESA ANGKASA RT 006 /RW 003, ANGKASA, BANDAR PETALANGAN, PELALAWAN, 28384 | S10: 0 | T10: 26264980 | U10: 0 | V10: 26264980 | W10: 0 | X10: 26264980 | Y10: EXP | Z10: 0 | AA10: 46154 | AB10: 17073000 | AC10: 17073000 | AD10: WINPAY | AE10: 0 | AF10: 9192743 | AG10: 0 | AH10: 46154 | AI10: Release | AJ10: 9192743 | AK10: 0.35 | AL10: 0.35 | AM10: -763 | AN10: -763 | AO10: 08. Sumbaguteng | AP10: PEKANBARU | AQ10: 12 | AR10: 26-05 | AS10: 24-11 | AT10: ALDA | AU10: FALSE | AV10: =IF(AQ10<=DAY(TODAY()),1,0) -> 0 | AW10: =IF(AQ10=DAY(TODAY()),1,0) -> 0
A11: Kalimantan | B11: 1521 | C11: Banjarmasin | D11: BANJARMASIN - MBL | E11: 4W | F11: 1521200000390 | G11: SITI FATIMAH | H11: 44165 | I11: 45657 | J11: SUZUKI | K11: CARRY PU 1.5 | L11: 2020 | M11: 081349302375 | O11: JL. SWADAYA RT 001 /RW 000, SUNGAI TABUK KERAMAT, SUNGAI TABUK, BANJAR, 70653 | P11: JL. SWADAYA RT 001 /RW 000, SUNGAI TABUK KERAMAT, SUNGAI TABUK, BANJAR, 70653 | Q11: JL. SWADAYA RT 001 /RW 000, SUNGAI TABUK KERAMAT, SUNGAI TABUK, BANJAR, 70653 | S11: 0 | T11: 24420010 | U11: 30000 | V11: 24450010 | W11: 4000 | X11: 24446010 | Y11: ICP | Z11: 20946010 | AA11: 46164 | AB11: 2975000 | AC11: 2975000 | AD11: WINPAY | AE11: 0 | AF11: 0 | AG11: 0 | AI11: On Hand | AK11: 0 | AL11: 0 | AM11: 20925010 | AN11: 20921010 | AO11: 05. Kalimantan | AP11: BANJARMASIN | AQ11: 22 | AR11: 26-05 | AS11: 24-12 | AT11: ALDA | AU11: FALSE | AV11: =IF(AQ11<=DAY(TODAY()),1,0) -> 0 | AW11: =IF(AQ11=DAY(TODAY()),1,0) -> 0
A12: Jateng | B12: 1510 | C12: Semarang | D12: SEMARANG - MBL | E12: 4W | F12: 1510210000030 | G12: SITI AMBARWATI | H12: 44218 | I12: 45678 | J12: SUZUKI | K12: CARRY PU 1.5 | L12: 2020 | M12: 083827937390 | O12: DSN GAYAM RT 006 /RW 002, KADIREJO, PABELAN, SEMARANG, 50771 | P12: DSN GAYAM RT 006 /RW 002, KADIREJO, PABELAN, SEMARANG, 50771 | Q12: DSN GAYAM RT 006 /RW 002, KADIREJO, PABELAN, SEMARANG, 50771 | S12: 0 | T12: 7434000 | U12: 220000 | V12: 7654000 | W12: 0 | X12: 7654000 | Y12: EXP | Z12: 0 | AA12: 46165 | AB12: 6123200 | AC12: 6123200 | AD12: WINPAY | AE12: 0 | AF12: 1530800 | AG12: 0 | AH12: 46167 | AI12: Release | AJ12: 1530800 | AK12: 0.2 | AL12: 0.2 | AM12: 0 | AN12: 0 | AO12: 03. Jawa Tengah | AP12: SEMARANG | AQ12: 23 | AR12: 26-05 | AS12: 25-01 | AT12: ALDA | AU12: FALSE | AV12: =IF(AQ12<=DAY(TODAY()),1,0) -> 0 | AW12: =IF(AQ12=DAY(TODAY()),1,0) -> 0
A13: Sulawesi | B13: 1547 | C13: Ternate | D13: TERNATE - MBL | E13: 4W | F13: 1547200000090 | G13: ROBERT E GARAWAI | H13: 44146 | I13: 45692 | J13: SUZUKI | K13: CARRY PU 1.5 | L13: 2020 | M13: 081223808699 | N13: 085731363100 | O13: SOAMAETEK RT 001 /RW 001, SOAMAETEK, KAO BARAT, HALMAHERA UTARA, 97764 | P13: SOAMAETEK RT 001 /RW 001, SOAMAETEK, KAO BARAT, HALMAHERA UTARA, 97764 | Q13: DESA SOAMAETEK RT 001 /RW 001, SOAMAETEK, KAO BARAT, HALMAHERA UTARA, 97764 | S13: 0 | T13: 0 | U13: 17340600 | V13: 17340600 | W13: 0 | X13: 17340600 | Y13: ICP | Z13: 13340600 | AA13: 46172 | AB13: 500000 | AC13: 500000 | AD13: WINPAY | AE13: 0 | AF13: 0 | AG13: 0 | AI13: On Hand | AK13: 0 | AL13: 0 | AM13: 13340600 | AN13: 13340600 | AO13: 06. Sulawesi | AP13: TERNATE | AQ13: 30 | AR13: 26-05 | AS13: 25-02 | AT13: ALDA | AU13: FALSE | AV13: =IF(AQ13<=DAY(TODAY()),1,0) -> 0 | AW13: =IF(AQ13=DAY(TODAY()),1,0) -> 0
A14: Jateng | B14: 1517 | C14: Purwokerto | D14: PURWOKERTO - MBL | E14: 4W | F14: 1517210000035 | G14: SUKATMAN | H14: 44242 | I14: 45699 | J14: SUZUKI | K14: CARRY PU 1.5 | L14: 2020 | M14: 081289819094 | O14: BEDANA RT 003 /RW 002, BEDANA, KALIBENING, BANJARNEGARA, 53458 | P14: BEDANA RT 003 /RW 002, BEDANA, KALIBENING, BANJARNEGARA, 53458 | Q14: BEDANA RT 003 /RW 002, BEDANA, KALIBENING, BANJARNEGARA, 53458 | S14: 0 | T14: 27933022 | U14: 0 | V14: 27933022 | W14: 0 | X14: 27933022 | Y14: ICP | Z14: 27633022 | AA14: 46167 | AB14: 300000 | AC14: 300000 | AD14: WINPAY | AE14: 0 | AF14: 0 | AG14: 0 | AI14: On Hand | AK14: 0 | AL14: 0 | AM14: 27608022 | AN14: 27608022 | AO14: 03. Jawa Tengah | AP14: PURWOKERTO | AQ14: 25 | AR14: 26-05 | AS14: 25-02 | AT14: ALDA | AU14: FALSE | AV14: =IF(AQ14<=DAY(TODAY()),1,0) -> 0 | AW14: =IF(AQ14=DAY(TODAY()),1,0) -> 0
A15: Sulawesi | B15: 1533 | C15: Manado | D15: MANADO - MBL | E15: 4W | F15: 1533200000308 | G15: MARSELLUS NAJOAN S PD | H15: 44205 | I15: 45701 | J15: SUZUKI | K15: ERTIGA | L15: 2020 | M15: 085298401416 | O15: JAGA V DESA KOKA KEC TOMBULU KAB MINAHASA RT 000 /RW 000, KOKA, TOMBULU, MINAHASA, 95661 | P15: JAGA V DESA KOKA KEC TOMBULU KAB MINAHASA RT 000 /RW 000, KOKA, TOMBULU, MINAHASA, 95661 | Q15: DESA KOKA KEC TOMBULU KAB MINAHASA RT 000 /RW 000, KOKA, TOMBULU, MINAHASA, 95661 | S15: 0 | T15: 11864342 | U15: 0 | V15: 11864342 | W15: 0 | X15: 11864342 | Y15: EXP | Z15: 0 | AA15: 46144 | AB15: 8306000 | AC15: 8306000 | AD15: WINPAY | AE15: 0 | AF15: 3558342.5 | AG15: 0 | AH15: 46144 | AI15: Release | AJ15: 3558342.5 | AK15: 0.3 | AL15: 0.3 | AM15: 0 | AN15: 0 | AO15: 06. Sulawesi | AP15: MANADO | AQ15: 2 | AR15: 26-05 | AS15: 25-02 | AT15: ALDA | AU15: FALSE | AV15: =IF(AQ15<=DAY(TODAY()),1,0) -> 1 | AW15: =IF(AQ15=DAY(TODAY()),1,0) -> 0
A16: Sulawesi | B16: 1540 | C16: Palu | D16: PALU - MOBIL | E16: 4W | F16: 1540200000235 | G16: MOHAMMAD WAHYU | H16: 44186 | I16: 45736 | J16: SUZUKI | K16: CARRY PU 1.5 | L16: 2020 | M16: 085241391226 | O16: DUSUN I KAMONJI RT 001 /RW 001, KAMONJI, BALAESANG, DONGGALA, 94355 | P16: DUSUN I KAMONJI RT 001 /RW 001, KAMONJI, BALAESANG, DONGGALA, 94355 | Q16: DESA KAMONJI RT 000 /RW 000, KAMONJI, BALAESANG, DONGGALA, 94355 | S16: 0 | T16: 25195125 | U16: 0 | V16: 25195125 | W16: 55000 | X16: 25140125 | Y16: EXP | Z16: 0 | AA16: 46147 | AB16: 17000000 | AC16: 17000000 | AD16: WINPAY | AE16: 0 | AF16: 8140125 | AG16: 0 | AH16: 46148 | AI16: Release | AJ16: 8140125 | AK16: 0.32 | AL16: 0.32 | AM16: 55000 | AN16: 0 | AO16: 06. Sulawesi | AP16: PALU | AQ16: 5 | AR16: 26-05 | AS16: 25-03 | AT16: ALDA | AU16: FALSE | AV16: =IF(AQ16<=DAY(TODAY()),1,0) -> 1 | AW16: =IF(AQ16=DAY(TODAY()),1,0) -> 1
A17: Jabodetabekser | B17: 1501 | C17: Kedoya | D17: KEDOYA - MBL | E17: 4W | F17: 1501210000107 | G17: SUTRISNO | H17: 44281 | I17: 45742 | J17: SUZUKI | K17: CARRY PU 1.5 | L17: 2021 | M17: 08129493843 | N17: 085945194884 | O17: JL MANGGA UBI NO 137 RT 006 /RW 007, KAPUK, CENGKARENG, JAKARTA BARAT, 11720 | P17: JL MANGGA UBI RT 006 /RW 007, KAPUK, CENGKARENG, JAKARTA BARAT, 11720 | Q17: JL MANGGA UBI RT 006 /RW 007, KAPUK, CENGKARENG, JAKARTA BARAT, 11720 | S17: 0 | T17: 17000 | U17: 0 | V17: 17000 | W17: 0 | X17: 17000 | Y17: EXP | Z17: 0 | AA17: 46154 | AB17: 17000 | AC17: 17000 | AD17: WINPAY | AE17: 0 | AF17: 0 | AG17: 0 | AH17: 46157 | AI17: Release | AK17: 0 | AL17: 0 | AM17: 0 | AN17: 0 | AO17: 01. Jabodetabekser | AP17: KEDOYA | AQ17: 12 | AR17: 26-05 | AS17: 25-03 | AT17: ALDA | AU17: FALSE | AV17: =IF(AQ17<=DAY(TODAY()),1,0) -> 0 | AW17: =IF(AQ17=DAY(TODAY()),1,0) -> 0
A18: Kalimantan | B18: 1553 | C18: Pontianak | D18: PONTIANAK - MBL | E18: 4W | F18: 1553210000006 | G18: MARKUS KARTONO | H18: 44221 | I18: 45762 | J18: SUZUKI | K18: CARRY PU 1.5 | L18: 2020 | M18: 081348768481 | O18: DUSUN ENTUBAH RT 004 /RW 000, ENGKAHAN, SEKAYAM, SANGGAU, 78556 | P18: DUSUN ENTUBAH RT 004 /RW 000, ENGKAHAN, SEKAYAM, SANGGAU, 78556 | Q18: DUSUN ENTUBAH RT 004 /RW 000, ENGKAHAN, SEKAYAM, SANGGAU, 78556 | S18: 0 | T18: 1462100 | U18: 4516635 | V18: 5978735 | W18: 0 | X18: 5978735 | Y18: EXP | Z18: 0 | AA18: 46151 | AB18: 4783000 | AC18: 4783000 | AD18: BANK | AE18: 0 | AF18: 1195735 | AG18: 0 | AH18: 46151 | AI18: Release | AJ18: 1195735 | AK18: 0.2 | AL18: 0.2 | AM18: 0 | AN18: 0 | AO18: 05. Kalimantan | AP18: PONTIANAK | AQ18: 9 | AR18: 26-05 | AS18: 25-04 | AT18: ALDA | AU18: FALSE | AV18: =IF(AQ18<=DAY(TODAY()),1,0) -> 0 | AW18: =IF(AQ18=DAY(TODAY()),1,0) -> 0
A19: Jateng | B19: 1524 | C19: Tegal | D19: TEGAL - MBL | E19: 4W | F19: 1524200000168 | G19: TARJANI | H19: 44062 | I19: 45803 | J19: SUZUKI | K19: CARRY PU 1.5 | L19: 2020 | M19: 081902119255 | O19: KETANGGUNGAN RT 03 /RW 05, KETANGGUNGAN, KETANGGUNGAN, BREBES, 52263 | P19: KETANGGUNGAN RT 03 /RW 05, KETANGGUNGAN, KETANGGUNGAN, BREBES, 52263 | Q19: KETANGGUNGAN RT 0 /RW 0, KETANGGUNGAN, KETANGGUNGAN, BREBES, 52263 | S19: 0 | T19: 1026500 | U19: 20429285 | V19: 21455785 | W19: 20000 | X19: 21435785 | Y19: ICP | Z19: 21135785 | AA19: 46172 | AB19: 200000 | AC19: 200000 | AD19: WINPAY | AE19: 0 | AF19: 0 | AG19: 0 | AI19: On Hand | AK19: 0 | AL19: 0 | AM19: 21155785 | AN19: 21135785 | AO19: 03. Jawa Tengah | AP19: TEGAL | AQ19: 30 | AR19: 26-05 | AS19: 25-05 | AT19: ALDA | AU19: FALSE | AV19: =IF(AQ19<=DAY(TODAY()),1,0) -> 0 | AW19: =IF(AQ19=DAY(TODAY()),1,0) -> 0
A20: Jateng | B20: 1515 | C20: Kudus | D20: KUDUS - MBL | E20: 4W | F20: 1515210000133 | G20: SUMARTONO | H20: 44327 | I20: 45807 | J20: SUZUKI | K20: CARRY PU 1.5 | L20: 2021 | M20: 085229563827 | N20: 082322929278 | O20: DUSUN GADUNGAN RT 010 /RW 001, SEJOMULYO, JUWANA, PATI, 59185 | P20: DUSUN GADUNGAN RT 010 /RW 001, SEJOMULYO, JUWANA, PATI, 59185 | Q20: DUAUN GADUNGAN RT 000 /RW 000, SEJOMULYO, JUWANA, PATI, 59185 | S20: 0 | T20: 12077000 | U20: 0 | V20: 12077000 | W20: 0 | X20: 12077000 | Y20: ICP | Z20: 12077000 | AA20: 46150 | AB20: 0 | AC20: 0 | AD20: WINPAY | AE20: 0 | AF20: 0 | AG20: 0 | AI20: On Hand | AK20: 0 | AL20: 0 | AM20: 12052000 | AN20: 12052000 | AO20: 03. Jawa Tengah | AP20: KUDUS | AQ20: 8 | AR20: 26-05 | AS20: 25-05 | AT20: ALDA | AU20: FALSE | AV20: =IF(AQ20<=DAY(TODAY()),1,0) -> 0 | AW20: =IF(AQ20=DAY(TODAY()),1,0) -> 0
A21: Jabar | B21: 1508 | C21: Karawang | D21: KARAWANG - MBL | E21: 4W | F21: 1508210000205 | G21: NIMIN | H21: 44302 | I21: 45824 | J21: SUZUKI | K21: CARRY PU 1.5 | L21: 2021 | M21: 088214520227 | O21: DUSUN RAWAINDAH RT 005 /RW 001, SEGARAN, BATUJAYA, KARAWANG, 41354 | P21: DUSUN RAWAINDAH RT 005 /RW 001, SEGARAN, BATUJAYA, KARAWANG, 41354 | Q21: DUSUN RAWAINDAH RT 005 /RW 001, SEGARAN, BATUJAYA, KARAWANG, 41354 | S21: 0 | T21: 0 | U21: 15787962 | V21: 15787962 | W21: 610000 | X21: 15177962 | Y21: EXP | Z21: 0 | AA21: 46161 | AB21: 11500000 | AC21: 11500000 | AD21: BANK | AE21: 0 | AF21: 3677962.5 | AG21: -11500000 | AH21: 46162 | AI21: Release | AJ21: 3677962.5 | AK21: 0.23 | AL21: 0.24 | AM21: 610000 | AN21: 0 | AO21: 02. Jawa Barat | AP21: KARAWANG | AQ21: 19 | AR21: 26-05 | AS21: 25-06 | AT21: ALDA | AU21: FALSE | AV21: =IF(AQ21<=DAY(TODAY()),1,0) -> 0 | AW21: =IF(AQ21=DAY(TODAY()),1,0) -> 0
A22: Jabodetabekser | B22: 1507 | C22: Tangerang | D22: TANGERANG - MBL | E22: 4W | F22: 1507210000221 | G22: AHMAD RUDI | H22: 44336 | I22: 45838 | J22: SUZUKI | K22: CARRY PU 1.5 | L22: 2021 | M22: 089513382086 | O22: JL.AKSES UI GG AMALIYAH RT 002 /RW 001, SRENGSENG SAWAH, JAGAKARSA, JAKARTA SELATAN, 12640 | P22: JL PINDING RT 02 /RW 01, CIPEDAK, JAGAKARSA, JAKARTA SELATAN, 12630 | Q22: JL AKSES UI GG HJ ALI RT 002 /RW 001, SRENGSENG SAWAH, JAGAKARSA, JAKARTA SELATAN, 12640 | S22: 0 | T22: 12483200 | U22: 0 | V22: 12483200 | W22: 0 | X22: 12483200 | Y22: ICP | Z22: 12483200 | AA22: 46149 | AB22: 0 | AC22: 0 | AD22: WINPAY | AE22: 0 | AF22: 0 | AG22: 0 | AI22: On Hand | AK22: 0 | AL22: 0 | AM22: 12458200 | AN22: 12458200 | AO22: 01. Jabodetabekser | AP22: TANGERANG | AQ22: 7 | AR22: 26-05 | AS22: 25-06 | AT22: ALDA | AU22: FALSE | AV22: =IF(AQ22<=DAY(TODAY()),1,0) -> 0 | AW22: =IF(AQ22=DAY(TODAY()),1,0) -> 0
A23: Jabodetabekser | B23: 1501 | C23: Kedoya | D23: KEDOYA - MBL | E23: 4W | F23: 1501210000232 | G23: SIRAT BIN AMAT | H23: 44376 | I23: 45859 | J23: SUZUKI | K23: CARRY PU 1.5 | L23: 2021 | M23: 087782266130 | O23: KOMP DEPAG NO 21 RT 004 /RW 003, KEDAUNG KALI ANGKE, CENGKARENG, JAKARTA BARAT, 11710 | P23: KOMP DEPAG NO 21 RT 004 /RW 003, KEDAUNG KALI ANGKE, CENGKARENG, JAKARTA BARAT, 11710 | Q23: KOMP DEPAG NO 21 RT 004 /RW 003, KEDAUNG KALI ANGKE, CENGKARENG, JAKARTA BARAT, 11710 | S23: 0 | T23: 124355 | U23: 6231665.2 | V23: 6356020.2 | W23: 0 | X23: 6356020.2 | Y23: ICP | Z23: 5456020.2 | AA23: 46168 | AB23: 100000 | AC23: 100000 | AD23: BANK | AE23: 0 | AF23: 0 | AG23: 0 | AI23: On Hand | AK23: 0 | AL23: 0 | AM23: 5429020.2 | AN23: 5429020.2 | AO23: 01. Jabodetabekser | AP23: KEDOYA | AQ23: 26 | AR23: 26-05 | AS23: 25-07 | AT23: ALDA | AU23: FALSE | AV23: =IF(AQ23<=DAY(TODAY()),1,0) -> 0 | AW23: =IF(AQ23=DAY(TODAY()),1,0) -> 0
A24: Jatim | B24: 1519 | C24: Gresik | D24: GRESIK - MBL | E24: 4W | F24: 1519220000158 | G24: HARI SUSANTO | H24: 44742 | I24: 45868 | J24: SUZUKI | K24: CARRY PU 1.5 | L24: 2022 | M24: 082143750984 | O24: DSN LAMONGAN RT 015 /RW 003, KALIPURO, PUNGGING, MOJOKERTO, 61384 | P24: DSN JANTI RT 002 /RW 002, JATILANGKUNG, PUNGGING, MOJOKERTO, 61384 | Q24: JLN MOJOSARI PACET KM 4 RT 000 /RW 000, PESANGGRAHAN, KUTOREJO, MOJOKERTO, 61383 | S24: 0 | T24: 31876300 | U24: 0 | V24: 31876300 | W24: 0 | X24: 31876300 | Y24: EXP | Z24: 0 | AA24: 46157 | AB24: 23908000 | AC24: 23908000 | AD24: WINPAY | AE24: 0 | AF24: 7969075 | AG24: 0 | AH24: 46160 | AI24: Release | AJ24: 7969075 | AK24: 0.25 | AL24: 0.25 | AM24: -775 | AN24: -775 | AO24: 04. Jawa Timur | AP24: GRESIK | AQ24: 15 | AR24: 26-05 | AS24: 25-07 | AT24: ALDA | AU24: FALSE | AV24: =IF(AQ24<=DAY(TODAY()),1,0) -> 0 | AW24: =IF(AQ24=DAY(TODAY()),1,0) -> 0
A25: Jabodetabekser | B25: 1506 | C25: Bekasi | D25: BEKASI - MBL | E25: 4W | F25: 1506240000202 | G25: RIZKI AKBAR | H25: 45534 | I25: 45876 | J25: SUZUKI | K25: JIMNY 5 DOOR | L25: 2024 | M25: 0817111080 | O25: SAFIRA RESIDENCE B/25 RT 005 /RW 005, PALUMBONSARI, KARAWANG TIMUR, KARAWANG, 41314 | P25: SAFIRA RESIDENCE B/25 RT 005 /RW 005, PALUMBONSARI, KARAWANG TIMUR, KARAWANG, 41314 | Q25: SAFIRA RESIDENCE B/25 RT 005 /RW 005, PALUMBONSARI, KARAWANG TIMUR, KARAWANG, 41314 | S25: 0 | T25: 1212560 | U25: 0 | V25: 1212560 | W25: 0 | X25: 1212560 | Y25: EXP | Z25: 0 | AA25: 46163 | AB25: 1212560 | AC25: 1212560 | AD25: WINPAY | AE25: 0 | AF25: 0 | AG25: 0 | AH25: 46163 | AI25: Release | AK25: 0 | AL25: 0 | AM25: 0 | AN25: 0 | AO25: 01. Jabodetabekser | AP25: BEKASI | AQ25: 21 | AR25: 26-05 | AS25: 25-08 | AT25: ALDA | AU25: FALSE | AV25: =IF(AQ25<=DAY(TODAY()),1,0) -> 0 | AW25: =IF(AQ25=DAY(TODAY()),1,0) -> 0
A26: Sumatera | B26: 1536 | C26: Bandar Lampung | D26: BANDAR LAMPUNG - MBL | E26: 4W | F26: 1536200000162 | G26: ALIN SYURYANA | H26: 44193 | I26: 45892 | J26: SUZUKI | K26: CARRY PU 1.5 | L26: 2020 | M26: 082378578648 | O26: JL. BERINGIN I BLOK.A2 NO.26 LK.III RT 000 /RW 000, BERINGIN RAYA, KEMILING, BANDAR LAMPUNG, 35158 | P26: JL.BERINGIN 1 BLOK A2 NO.26 LK.III RT 001 /RW 000, BERINGIN RAYA, KEMILING, BANDAR LAMPUNG, 35158 | Q26: JL BERINGIN I BLOK A2 NO.26 LK.III RT 001 /RW 000, BERINGIN RAYA, KEMILING, BANDAR LAMPUNG, 35158 | S26: 0 | T26: 6824500 | U26: 18830175 | V26: 25654675 | W26: 163000 | X26: 25491675 | Y26: EXP | Z26: 0 | AA26: 46161 | AB26: 17696402 | AC26: 17696402 | AD26: BANK | AE26: 0 | AF26: 7933273 | AG26: -17696402 | AH26: 46162 | AI26: Release | AJ26: 7933273 | AK26: 0.31 | AL26: 0.31 | AM26: 0 | AN26: -163000 | AO26: 07. Sumbagsel | AP26: BANDAR LAMPUNG | AQ26: 19 | AR26: 26-05 | AS26: 25-08 | AT26: ALDA | AU26: FALSE | AV26: =IF(AQ26<=DAY(TODAY()),1,0) -> 0 | AW26: =IF(AQ26=DAY(TODAY()),1,0) -> 0
A27: Kalimantan | B27: 1521 | C27: Banjarmasin | D27: BANJARMASIN - MBL | E27: 4W | F27: 1521210000210 | G27: SALEHAH | H27: 44474 | I27: 45895 | J27: SUZUKI | K27: CARRY PU 1.5 | L27: 2021 | M27: 082151356596 | O27: KARANG INDAH RT 001 /RW 001, KARANG INDAH, ANGSANA, TANAH BUMBU, 72275 | P27: KARANG INDAH RT 001 /RW 001, KARANG INDAH, ANGSANA, TANAH BUMBU, 72275 | Q27: KARANG INDAH RT 000 /RW 000, KARANG INDAH, ANGSANA, TANAH BUMBU, 72275 | S27: 0 | T27: 14427420 | U27: 0 | V27: 14427420 | W27: 0 | X27: 14427420 | Y27: ICP | Z27: 13277420 | AA27: 46170 | AB27: 600000 | AC27: 600000 | AD27: WINPAY | AE27: 0 | AF27: 0 | AG27: 0 | AI27: On Hand | AK27: 0 | AL27: 0 | AM27: 13277420 | AN27: 13277420 | AO27: 05. Kalimantan | AP27: BANJARMASIN | AQ27: 28 | AR27: 26-05 | AS27: 25-08 | AT27: ALDA | AU27: FALSE | AV27: =IF(AQ27<=DAY(TODAY()),1,0) -> 0 | AW27: =IF(AQ27=DAY(TODAY()),1,0) -> 0
A28: IBT | B28: 1531 | C28: Kupang | D28: KUPANG - MBL | E28: 4W | F28: 1531210000176 | G28: MARTEN MANTOLAS | H28: 44415 | I28: 45895 | J28: SUZUKI | K28: CARRY PU 1.5 | L28: 2021 | M28: 085216610989 | O28: JLN PERINTIS KEMERDEKAAN RT 020 /RW 006, KAYA PUTIH, OEBOBO, KUPANG, 85111 | P28: JL LAKBANU II RT 045 /RW 001, LILIBA, OEBOBO, KUPANG, 85111 | Q28: JLN PERINTIS KEMERDEKAAN RT 020 /RW 006, KAYU PUTIH , OEBOBO, KUPANG , 85111 | S28: 0 | T28: 4518792 | U28: 0 | V28: 4518792 | W28: 920 | X28: 4517872 | Y28: EXP | Z28: 0 | AA28: 46160 | AB28: 3616000 | AC28: 3616000 | AD28: WINPAY | AE28: 0 | AF28: 902792 | AG28: 0 | AH28: 46160 | AI28: Release | AJ28: 902792 | AK28: 0.2 | AL28: 0.2 | AM28: 0 | AN28: -920 | AO28: 09. IBT | AP28: KUPANG | AQ28: 18 | AR28: 26-05 | AS28: 25-08 | AT28: ALDA | AU28: FALSE | AV28: =IF(AQ28<=DAY(TODAY()),1,0) -> 0 | AW28: =IF(AQ28=DAY(TODAY()),1,0) -> 0
A29: Kalimantan | B29: 1521 | C29: Banjarmasin | D29: BANJARMASIN - MBL | E29: 4W | F29: 1521210000106 | G29: H KASPUL ANWAR | H29: 44347 | I29: 45930 | J29: SUZUKI | K29: CARRY PU 1.5 | L29: 2021 | M29: 082154123227 | O29: JL.A.YANI RT 003 /RW 001, KINTAPURA, KINTAP, TANAH LAUT, 70883 | P29: JL.A.YANI RT 003 /RW 001, KINTAPURA, KINTAP, TANAH LAUT, 70883 | Q29: JL.A.YANI RT 003 /RW 001, KINTAPURA, KINTAP, TANAH LAUT, 70883 | S29: 0 | T29: 6824750 | U29: 11762569 | V29: 18587319 | W29: 0 | X29: 18587319 | Y29: ICP | Z29: 17562319 | AA29: 46160 | AB29: 1025000 | AC29: 1025000 | AD29: WINPAY | AE29: 0 | AF29: 0 | AG29: 0 | AI29: On Hand | AK29: 0 | AL29: 0 | AM29: 17562319 | AN29: 17562319 | AO29: 05. Kalimantan | AP29: BANJARMASIN | AQ29: 18 | AR29: 26-05 | AS29: 25-09 | AT29: ALDA | AU29: FALSE | AV29: =IF(AQ29<=DAY(TODAY()),1,0) -> 0 | AW29: =IF(AQ29=DAY(TODAY()),1,0) -> 0
A30: Jabodetabekser | B30: 1507 | C30: Tangerang | D30: TANGERANG - MBL | E30: 4W | F30: 1507220000426 | G30: SOHIBI | H30: 44839 | I30: 45945 | J30: SUZUKI | K30: CARRY PU 1.5 | L30: 2022 | M30: 081991709337 | O30: JL OSCAR 2 NO 96 RT 01 /RW 02, BAMBU APUS, PAMULANG, TANGERANG SELATAN, 15415 | P30: CENDANA RESIDENCE BLOK E7 NO.12 RT 008 /RW 004, SERUA, CIPUTAT, TANGERANG SELATAN, 15414 | Q30: JL SUMUR WATU DESA KEBOCORAN NO 21 RT 04 /RW 01, KEDUNGGEDE, BANYUMAS, BANYUMAS, 53192 | S30: 0 | T30: 9633000 | U30: 0 | V30: 9633000 | W30: 0 | X30: 9633000 | Y30: EXP | Z30: 0 | AA30: 46153 | AB30: 7707000 | AC30: 7707000 | AD30: WINPAY | AE30: 0 | AF30: 1926000 | AG30: 0 | AH30: 46154 | AI30: Release | AJ30: 1926000 | AK30: 0.2 | AL30: 0.2 | AM30: 0 | AN30: 0 | AO30: 01. Jabodetabekser | AP30: TANGERANG | AQ30: 11 | AR30: 26-05 | AS30: 25-10 | AT30: ALDA | AU30: FALSE | AV30: =IF(AQ30<=DAY(TODAY()),1,0) -> 0 | AW30: =IF(AQ30=DAY(TODAY()),1,0) -> 0
A31: Kalimantan | B31: 1511 | C31: Samarinda | D31: SAMARINDA - MBL | E31: 4W | F31: 1511210000203 | G31: FITRIANSYAH | H31: 44500 | I31: 45947 | J31: SUZUKI | K31: CARRY PU 1.5 | L31: 2021 | M31: 081347900213 | O31: JL. ERLIAN RT 001 /RW 000, SANGGULAN, SEBULU, KUTAI KARTANEGARA, 75552 | P31: JL. ERLIAN RT 001 /RW 000, SANGGULAN, SEBULU, KUTAI KARTANEGARA, 75552 | Q31: JL.ERLIAN RT 001 /RW 000, SANGGULAN, SEBULU, KUTAI KARTANEGARA, 75552 | S31: 0 | T31: 11712978 | U31: 0 | V31: 11712978 | W31: 100000 | X31: 11612978 | Y31: RRD | Z31: 0 | AA31: 46167 | AB31: 10000000 | AC31: 10000000 | AD31: WINPAY | AE31: 0 | AF31: 1612978 | AG31: 0 | AH31: 46167 | AI31: On Hand | AJ31: 1612978 | AK31: 0.14 | AL31: 0.14 | AM31: 100000 | AN31: 0 | AO31: 05. Kalimantan | AP31: SAMARINDA | AQ31: 25 | AR31: 26-05 | AS31: 25-10 | AT31: ALDA | AU31: FALSE | AV31: =IF(AQ31<=DAY(TODAY()),1,0) -> 0 | AW31: =IF(AQ31=DAY(TODAY()),1,0) -> 0
A32: Sumatera | B32: 1520 | C32: Pekan Baru | D32: PEKANBARU - MBL | E32: 4W | F32: 1520210000325 | G32: EVITRI HANDAYANI | H32: 44488 | I32: 45950 | J32: SUZUKI | K32: CARRY PU 1.5 | L32: 2021 | M32: 082386034436 | O32: JL.SUKUN RT 001 /RW 003, RANTAU BERTUAH, MINAS, SIAK, 28685 | P32: JL.SUKUN RT 001 /RW 003, RANTAU BERTUAH, MINAS, SIAK, 28685 | Q32: JL.SUKUN RT 001 /RW 003, RANTAU BERTUAH, MINAS, SIAK, 28685 | S32: 0 | T32: 106640 | U32: 0 | V32: 106640 | W32: 470 | X32: 106170 | Y32: EXP | Z32: 0 | AA32: 46146 | AB32: 106640 | AC32: 106640 | AD32: WINPAY | AE32: 0 | AF32: 0 | AG32: 0 | AH32: 46146 | AI32: Release | AK32: 0 | AL32: 0 | AM32: 0 | AN32: -470 | AO32: 08. Sumbaguteng | AP32: PEKANBARU | AQ32: 4 | AR32: 26-05 | AS32: 25-10 | AT32: ALDA | AU32: FALSE | AV32: =IF(AQ32<=DAY(TODAY()),1,0) -> 1 | AW32: =IF(AQ32=DAY(TODAY()),1,0) -> 0
A33: Jabodetabekser | B33: 1501 | C33: Kedoya | D33: KEDOYA - MBL | E33: 4W | F33: 1501210000358 | G33: FERI FADLI | H33: 44462 | I33: 45954 | J33: SUZUKI | K33: CARRY PU 1.5 | L33: 2021 | M33: 089662536610 | O33: KP PERIGI KOONG RT 005 /RW 007, BEDAHAN, SAWANGAN, DEPOK, 16519 | P33: KP PERIGI KOONG RT 005 /RW 007, BEDAHAN, SAWANGAN, DEPOK, 16519 | Q33: KP PERIGI KOONG RT 005 /RW 007, BEDAHAN, SAWANGAN, DEPOK, 16519 | S33: 0 | T33: 2002805 | U33: 0 | V33: 2002805 | W33: 0 | X33: 2002805 | Y33: EXP | Z33: 0 | AA33: 46149 | AB33: 2002805 | AC33: 2002805 | AD33: WINPAY | AE33: 0 | AF33: 0 | AG33: 0 | AH33: 46150 | AI33: Release | AK33: 0 | AL33: 0 | AM33: 0 | AN33: 0 | AO33: 01. Jabodetabekser | AP33: KEDOYA | AQ33: 7 | AR33: 26-05 | AS33: 25-10 | AT33: ALDA | AU33: FALSE | AV33: =IF(AQ33<=DAY(TODAY()),1,0) -> 0 | AW33: =IF(AQ33=DAY(TODAY()),1,0) -> 0
A34: Kalimantan | B34: 1537 | C34: Palangkaraya | D34: PALANGKARAYA - MBL | E34: 4W | F34: 1537210000175 | G34: BERLIAGO | H34: 44498 | I34: 45965 | J34: SUZUKI | K34: CARRY PU 1.5 | L34: 2021 | M34: 085388740068 | O34: JL DAMANG EITHEL RABU RT 006 /RW 0, PUJON, KAPUAS TENGAH, KAPUAS, 73555 | P34: JL DAMANG EITHEL RABU RT 006 /RW 0, PUJON, KAPUAS TENGAH, KAPUAS, 73555 | Q34: JL. DAMANG EITHEL RABU RT 006 /RW 00, PUJON, KAPUAS TENGAH, KAPUAS, 73555 | S34: 0 | T34: 5195480 | U34: 0 | V34: 5195480 | W34: 0 | X34: 5195480 | Y34: EXP | Z34: 0 | AA34: 46147 | AB34: 5196000 | AC34: 5196000 | AD34: WINPAY | AE34: 0 | AF34: 0 | AG34: 0 | AH34: 46147 | AI34: Release | AK34: 0 | AL34: 0 | AM34: -520 | AN34: -520 | AO34: 05. Kalimantan | AP34: PALANGKARAYA | AQ34: 5 | AR34: 26-05 | AS34: 25-11 | AT34: ALDA | AU34: FALSE | AV34: =IF(AQ34<=DAY(TODAY()),1,0) -> 1 | AW34: =IF(AQ34=DAY(TODAY()),1,0) -> 1
A35: Kalimantan | B35: 1521 | C35: Banjarmasin | D35: BANJARMASIN - MBL | E35: 4W | F35: 1521200000279 | G35: ARYA DANY | H35: 44076 | I35: 45967 | J35: SUZUKI | K35: ERTIGA | L35: 2020 | M35: 087753626920 | N35: 081943651300 | O35: JL. PROPINSI RT 001 /RW 002, SEI/SUNGAI CUKA, SATUI, TANAH BUMBU, 72275 | P35: JL. PROPINSI RT 001 /RW 002, SEI/SUNGAI CUKA, SATUI, TANAH BUMBU, 72275 | Q35: JL. PROPINSI RT 001 /RW 002, SEI/SUNGAI CUKA, SATUI, TANAH BUMBU, 72275 | S35: 0 | T35: 0 | U35: 17774425 | V35: 17774425 | W35: 950000 | X35: 16824425 | Y35: ICP | Z35: 15849425 | AA35: 46172 | AB35: 500000 | AC35: 500000 | AD35: WINPAY | AE35: 0 | AF35: 0 | AG35: 0 | AI35: On Hand | AK35: 0 | AL35: 0 | AM35: 16774425 | AN35: 15824425 | AO35: 05. Kalimantan | AP35: BANJARMASIN | AQ35: 30 | AR35: 26-05 | AS35: 25-11 | AT35: ALDA | AU35: FALSE | AV35: =IF(AQ35<=DAY(TODAY()),1,0) -> 0 | AW35: =IF(AQ35=DAY(TODAY()),1,0) -> 0
A36: Sumatera | B36: 1535 | C36: Palembang | D36: PALEMBANG 4 - MBL | E36: 4W | F36: 1535210000055 | G36: EDI DERIYANTO | H36: 44284 | I36: 45978 | J36: SUZUKI | K36: CARRY PU 1.5 | L36: 2021 | M36: 081271469777 | O36: JL.ANGGREK UJUNG NO 2023 RT 17 /RW 4, 5 ILIR, ILIR TIMUR II, PALEMBANG, 30115 | P36: JL ANGGREK UJUNG NO 2023 RT 017 /RW 004, 5 ILIR, ILIR TIMUR II, PALEMBANG, 30115 | Q36: JL ANGGREK UJUNG NO 2023 RT 017 /RW 004, 5 ILIR, ILIR TIMUR II, PALEMBANG, 30115 | S36: 0 | T36: 13480170 | U36: 4603901 | V36: 18084071 | W36: 40390 | X36: 18043681 | Y36: ICP | Z36: 17943681 | AA36: 46168 | AB36: 100000 | AC36: 100000 | AD36: BANK | AE36: 0 | AF36: 0 | AG36: 0 | AI36: On Hand | AK36: 0 | AL36: 0 | AM36: 17984071 | AN36: 17943681 | AO36: 07. Sumbagsel | AP36: PALEMBANG | AQ36: 26 | AR36: 26-05 | AS36: 25-11 | AT36: ALDA | AU36: FALSE | AV36: =IF(AQ36<=DAY(TODAY()),1,0) -> 0 | AW36: =IF(AQ36=DAY(TODAY()),1,0) -> 0
A37: Sumatera | B37: 1522 | C37: Medan | D37: MEDAN - MBL | E37: 4W | F37: 1522210000161 | G37: ALBOINTA PANDIA | H37: 44500 | I37: 45991 | J37: SUZUKI | K37: CARRY PU 1.5 | L37: 2021 | M37: 082177445557 | O37: JL SIMPANG KONGSI GG SINABUNG II DUSUN III RT 00 /RW 00, BARU (DESA BARU), PANCUR BATU, DELI SERDANG, 20353 | P37: JL JAMIN GINTING GG SWADAYA MEDAN RT 000 /RW 000, MANGGA, MEDAN TUNTUNGAN, MEDAN, 20141 | Q37: JL WILLIAM ISKANDAR PAJAK MMTC RT 000 /RW 000, TEMBUNG, MEDAN TEMBUNG, MEDAN, 20225 | S37: 0 | T37: 7527955 | U37: 3385615 | V37: 10913570 | W37: 0 | X37: 10913570 | Y37: EXP | Z37: 0 | AA37: 46162 | AB37: 7650000 | AC37: 7650000 | AD37: WINPAY | AE37: 0 | AF37: 3263570 | AG37: 0 | AH37: 46163 | AI37: Release | AJ37: 3263570 | AK37: 0.3 | AL37: 0.3 | AM37: 0 | AN37: 0 | AO37: 08. Sumbaguteng | AP37: MEDAN | AQ37: 20 | AR37: 26-05 | AS37: 25-11 | AT37: ALDA | AU37: FALSE | AV37: =IF(AQ37<=DAY(TODAY()),1,0) -> 0 | AW37: =IF(AQ37=DAY(TODAY()),1,0) -> 0
A38: Sulawesi | B38: 1514 | C38: Makassar | D38: MAKASSAR - MBL | E38: 4W | F38: 1514200000322 | G38: ISA | H38: 44125 | I38: 45991 | J38: SUZUKI | K38: CARRY PU 1.5 | L38: 2020 | M38: 081356004813 | N38: 082395864799 | O38: BALANG LOE RT 002 /RW 002, BALANG BERU, BINAMU, JENEPONTO, 92316 | P38: BALANG LOE RT 002 /RW 002, BALANG BERU, BINAMU, JENEPONTO, 92316 | Q38: BARANG LOE RT 000 /RW 000, BALANG BERU, BINAMU, JENEPONTO, 92316 | S38: 0 | T38: 27855125 | U38: 13635660 | V38: 41490785 | W38: 0 | X38: 41490785 | Y38: RRD | Z38: 0 | AA38: 46170 | AB38: 26971000 | AC38: 26971000 | AD38: WINPAY | AE38: 0 | AF38: 14519785 | AG38: 0 | AH38: 46171 | AI38: On Hand | AJ38: 14519785 | AK38: 0.35 | AL38: 0.35 | AM38: 0 | AN38: 0 | AO38: 06. Sulawesi | AP38: MAKASSAR | AQ38: 28 | AR38: 26-05 | AS38: 25-11 | AT38: ALDA | AU38: FALSE | AV38: =IF(AQ38<=DAY(TODAY()),1,0) -> 0 | AW38: =IF(AQ38=DAY(TODAY()),1,0) -> 0
A39: Jatim | B39: 1519 | C39: Gresik | D39: GRESIK - MBL | E39: 4W | F39: 1519210000290 | G39: GITA RATNA ANUGRAINI | H39: 44538 | I39: 46007 | J39: SUZUKI | K39: CARRY PU 1.5 | L39: 2021 | M39: 085259229855 | O39: DUSUN BARAT RT 001 /RW 002, KLOTOK, BALONG PANGGANG, GRESIK, 61173 | P39: DUSUN BARAT RT 001 /RW 002, KLOTOK, BALONG PANGGANG, GRESIK, 61173 | Q39: DSN BARAT RT 001 /RW 002, KLOTOK, BALONG PANGGANG, GRESIK, 61173 | S39: 0 | T39: 92000 | U39: 0 | V39: 92000 | W39: 0 | X39: 92000 | Y39: EXP | Z39: 0 | AA39: 46146 | AB39: 0 | AC39: 0 | AD39: WINPAY | AE39: 0 | AF39: 0 | AG39: -3750000 | AH39: 46014 | AI39: Release | AK39: 0 | AL39: 0 | AM39: -309500 | AN39: -309500 | AO39: 04. Jawa Timur | AP39: GRESIK | AQ39: 4 | AR39: 26-05 | AS39: 25-12 | AT39: ALDA | AU39: FALSE | AV39: =IF(AQ39<=DAY(TODAY()),1,0) -> 1 | AW39: =IF(AQ39=DAY(TODAY()),1,0) -> 0
A40: Sulawesi | B40: 1533 | C40: Manado | D40: MANADO - MBL | E40: 4W | F40: 1533210000081 | G40: DJELITA RAHEL LOMBOAN | H40: 44310 | I40: 46022 | J40: SUZUKI | K40: CARRY PU 1.5 | L40: 2021 | M40: 082188793907 | N40: 085240045745 | O40: LINGK I KEL MASARANG KEC TONDANO BARAT KAB MINAHASA RT 0 /RW 0, MASARANG, TONDANO BARAT, MINAHASA, 95616 | P40: LINGK II KEL TUMATANGTANG SATU KEC TOMOHON SELATAN KOTA TOMOHON RT 0 /RW 0, TUMATANGTANG SATU , TOMOHON SELATAN, TOMOHON, 95439 | Q40: PASAR TONDANO KEL WAWALINTOUAN KEC TONDANO BARAT KAB MINAHASA RT 000 /RW 000, WAWALINTOUAN, TONDANO BARAT, MINAHASA, 95616 | S40: 0 | T40: 13892650 | U40: 39246950 | V40: 53139600 | W40: 0 | X40: 53139600 | Y40: EXP | Z40: 0 | AA40: 46167 | AB40: 34541000 | AC40: 34541000 | AD40: WINPAY | AE40: 0 | AF40: 18598600 | AG40: -25000 | AH40: 46167 | AI40: Release | AJ40: 18598600 | AK40: 0.35 | AL40: 0.35 | AM40: -25000 | AN40: -25000 | AO40: 06. Sulawesi | AP40: MANADO | AQ40: 25 | AR40: 26-05 | AS40: 25-12 | AT40: ALDA | AU40: FALSE | AV40: =IF(AQ40<=DAY(TODAY()),1,0) -> 0 | AW40: =IF(AQ40=DAY(TODAY()),1,0) -> 0
...

Sheet DB
A1: AREA | B1: BRANCHID | C1: CABANG_MERGER | D1: CABANG | E1: BUSINESS_UNIT | F1: NOMOR_KONTRAK | G1: NAMA_DEBITUR | H1: GO_LIVE_DATE | I1: TANGGAL_BAYAR_ANGS_TERAKHIR | J1: MERK_KENDARAAN | K1: TYPE_KENDARAAN | L1: TAHUN_KENDARAAN | M1: NO_HP_1 | N1: NO_HP_2 | O1: RESIDENCE_ADDRESS | P1: LEGAL_ADDRESS | Q1: JOB_ADDRESS | R1: EMERGENCY_ADDRESS | S1: OS_PRINCIPAL_AMT | T1: OS_LC_INST_AMT | U1: OS_CHARGE_RCV_AMT | V1: TOTAL_AMOUNT_TO_BE_PAID_1 | W1: PREPAID | X1: TOTAL_KEWAJIBAN | Y1: CONTRACT_STAT | Z1: TOTAL_AMOUNT_TO_BE_PAID_2 | AA1: TGL_PEMBAYARAN | AB1: AMOUNT_PEMBAYARAN_1 | AC1: AMOUNT_PEMBAYARAN | AD1: WOP | AE1: AMOUNT_WOP | AF1: WAIVE_AMOUNT_1 | AG1: REVERSAL | AH1: TGL_RRD | AI1: STATUS_BPKB | AJ1: WAIVE_AMOUNT_2 | AK1: WAIVE_PCTG_MIN_TOTAL_AMOUNT_TO_BE_PAID | AL1: WAIVE_PCTG_MIN_TOTAL_KEWAJIBAN | AM1: VERIFIKASI_MIN_TOTAL_AMOUNT_TO_BE_PAID | AN1: VERIFIKASI_MIN_TOTAL_KEWAJIBAN | AO1: New Area | AP1: New Cabang | AQ1: Tgl ( TGL_PEMBAYARAN ) | AR1: Periode ( TGL_PEMBAYARAN ) | AS1: Periode ( TANGGAL_BAYAR_ANGS_TERAKHIR ) | AT1: Flag Alda / Aktif | AU1: Cek Alda / Aktif | AV1: Unit Pakai
A2: Jabodetabekser | B2: 1506 | C2: Bekasi | D2: BEKASI - MBL | E2: 4W | F2: 1506220000166 | G2: AGUS ERLAN HUTABARAT | H2: 44721 | I2: 46174 | J2: SUZUKI | K2: CARRY PU 1.5 | L2: 2022 | M2: 081315423489 | O2: PERUMAHAN CITRA INDAH CLUSTER BUKIT CENDANA RT 000 /RW 000, SUKAMAJU, JONGGOL, BOGOR, 16830 | P2: JL MANUNGGAL II RT 012 /RW 002, PETUKANGAN SELATAN, PESANGGRAHAN, JAKARTA SELATAN, 12270 | Q2: PERUM CITRA INDAH CITY BUKIT BOUGENVILE LUAR AI 00 NO 18 RT 001 /RW 008, SINGAJAYA, JONGGOL, BOGOR, 16830 | S2: 0 | T2: 341630.5 | U2: 0 | V2: 341630.5 | W2: 0 | X2: 341630.5 | Y2: LIV | Z2: 341630.5 | AA2: 46176 | AB2: 341631 | AC2: 0 | AD2: WINPAY | AE2: 0 | AF2: 0 | AG2: 0 | AI2: On Hand | AK2: 0 | AL2: 0 | AM2: -0.5 | AN2: -0.5 | AO2: =VLOOKUP(hcp[[#This Row],[BRANCHID]],'New KC'!$A:$K,8,0) -> 01. Jabodetabekser | AP2: =VLOOKUP(hcp[[#This Row],[BRANCHID]],'New KC'!$A:$K,9,0) -> BEKASI | AQ2: =DAY(hcp[[#This Row],[TGL_PEMBAYARAN]]) -> 3 | AR2: =TEXT(hcp[[#This Row],[TGL_PEMBAYARAN]],"YY-MM") -> 26-06 | AS2: =TEXT(hcp[[#This Row],[TANGGAL_BAYAR_ANGS_TERAKHIR]],"YY-MM") -> 26-06 | AT2: =IF(hcp[[#This Row],[Periode ( TANGGAL_BAYAR_ANGS_TERAKHIR )]]=hcp[[#This Row],[Periode ( TGL_PEMBAYARAN )]],"AKTIF","ALDA") -> AKTIF | AU2: =hcp[[#This Row],[Periode ( TANGGAL_BAYAR_ANGS_TERAKHIR )]]=hcp[[#This Row],[Periode ( TGL_PEMBAYARAN )]] -> TRUE | AV2: =IF(hcp[[#This Row],[Tgl ( TGL_PEMBAYARAN )]]=DAY(TODAY()),1,0) -> 0
A3: Jateng | B3: 1510 | C3: Semarang | D3: SEMARANG - MBL | E3: 4W | F3: 1510220000132 | G3: NANDA SATRIA AGUST PANGESTU | H3: 44709 | I3: 46175 | J3: SUZUKI | K3: CARRY PU 1.5 | L3: 2022 | M3: 081904487819 | N3: 089670355537 | O3: KALISEGORO RT 004 /RW 001, KALISEGORO, GUNUNGPATI, SEMARANG, 50229 | P3: KALISEGORO RT 004 /RW 001, KALISEGORO, GUNUNGPATI, SEMARANG, 50229 | Q3: PASAR BANDARJO UNGARAN RT 000 /RW 000, BANDARJO, UNGARAN BARAT, SEMARANG, 50517 | S3: 0 | T3: 0 | U3: 2270000 | V3: 2270000 | W3: 1661000 | X3: 609000 | Y3: RRD | Z3: 0 | AA3: 46176 | AB3: 609000 | AC3: 0 | AD3: WINPAY | AE3: 0 | AF3: 0 | AG3: 0 | AH3: 46176 | AI3: On Hand | AK3: 0 | AL3: 0 | AM3: 1661000 | AN3: 0 | AO3: =VLOOKUP(hcp[[#This Row],[BRANCHID]],'New KC'!$A:$K,8,0) -> 03. Jawa Tengah | AP3: =VLOOKUP(hcp[[#This Row],[BRANCHID]],'New KC'!$A:$K,9,0) -> SEMARANG | AQ3: =DAY(hcp[[#This Row],[TGL_PEMBAYARAN]]) -> 3 | AR3: =TEXT(hcp[[#This Row],[TGL_PEMBAYARAN]],"YY-MM") -> 26-06 | AS3: =TEXT(hcp[[#This Row],[TANGGAL_BAYAR_ANGS_TERAKHIR]],"YY-MM") -> 26-06 | AT3: =IF(hcp[[#This Row],[Periode ( TANGGAL_BAYAR_ANGS_TERAKHIR )]]=hcp[[#This Row],[Periode ( TGL_PEMBAYARAN )]],"AKTIF","ALDA") -> AKTIF | AU3: =hcp[[#This Row],[Periode ( TANGGAL_BAYAR_ANGS_TERAKHIR )]]=hcp[[#This Row],[Periode ( TGL_PEMBAYARAN )]] -> TRUE | AV3: =IF(hcp[[#This Row],[Tgl ( TGL_PEMBAYARAN )]]=DAY(TODAY()),1,0) -> 0
A4: Jatim | B4: 1504 | C4: Surabaya | D4: SURABAYA - MBL | E4: 4W | F4: 1504200000317 | G4: OCTA | H4: 44033 | I4: 45492 | J4: SUZUKI | K4: CARRY PU 1.5 | L4: 2020 | M4: 081336646857 | O4: DUSUN KRAJAN WETAN RT 001 /RW 003, WONOSOBO, SRONO, BANYUWANGI, 68471 | P4: DUSUN KRAJAN WETAN RT 001 /RW 003, WONOSOBO, SRONO, BANYUWANGI, 68471 | Q4: DUSUN KRAJAN WETAN RT 001 /RW 003, WONOSOBO, SRONO, BANYUWANGI, 68471 | S4: 0 | T4: 709200 | U4: 0 | V4: 709200 | W4: 0 | X4: 709200 | Y4: RRD | Z4: 0 | AA4: 46176 | AB4: 709200 | AC4: 709200 | AD4: BANK | AE4: 0 | AF4: 0 | AG4: 0 | AH4: 46176 | AI4: On Hand | AK4: 0 | AL4: 0 | AM4: 0 | AN4: 0 | AO4: =VLOOKUP(hcp[[#This Row],[BRANCHID]],'New KC'!$A:$K,8,0) -> 04. Jawa Timur | AP4: =VLOOKUP(hcp[[#This Row],[BRANCHID]],'New KC'!$A:$K,9,0) -> SURABAYA | AQ4: =DAY(hcp[[#This Row],[TGL_PEMBAYARAN]]) -> 3 | AR4: =TEXT(hcp[[#This Row],[TGL_PEMBAYARAN]],"YY-MM") -> 26-06 | AS4: =TEXT(hcp[[#This Row],[TANGGAL_BAYAR_ANGS_TERAKHIR]],"YY-MM") -> 24-07 | AT4: =IF(hcp[[#This Row],[Periode ( TANGGAL_BAYAR_ANGS_TERAKHIR )]]=hcp[[#This Row],[Periode ( TGL_PEMBAYARAN )]],"AKTIF","ALDA") -> ALDA | AU4: =hcp[[#This Row],[Periode ( TANGGAL_BAYAR_ANGS_TERAKHIR )]]=hcp[[#This Row],[Periode ( TGL_PEMBAYARAN )]] -> FALSE | AV4: =IF(hcp[[#This Row],[Tgl ( TGL_PEMBAYARAN )]]=DAY(TODAY()),1,0) -> 0
A5: Kalimantan | B5: 1521 | C5: Banjarmasin | D5: BANJARMASIN - MBL | E5: 4W | F5: 1521220000128 | G5: CV NAGRI KANAKA FIRDAUS | H5: 44740 | I5: 46143 | J5: SUZUKI | K5: CARRY PU 1.5 | L5: 2022 | O5: PERUMAHAN LISTRIK 2 NO. 34 RT 005 /RW 004, GUNTUNG PAIKAT, BANJAR BARU SELATAN, BANJARBARU, 70713 | P5: PERUMAHAN LISTRIK 2 NO. 34 RT 005 /RW 004, GUNTUNG PAIKAT, BANJAR BARU SELATAN, BANJARBARU, 70713 | S5: 0 | T5: 100490 | U5: 1410426 | V5: 1510916 | W5: 0 | X5: 1510916 | Y5: ICP | Z5: 100490 | AA5: 46176 | AB5: 1510916 | AC5: 1510916 | AD5: WINPAY | AE5: 0 | AF5: 0 | AG5: 0 | AI5: On Hand | AK5: 0 | AL5: 0 | AM5: 0 | AN5: 0 | AO5: =VLOOKUP(hcp[[#This Row],[BRANCHID]],'New KC'!$A:$K,8,0) -> 05. Kalimantan | AP5: =VLOOKUP(hcp[[#This Row],[BRANCHID]],'New KC'!$A:$K,9,0) -> BANJARMASIN | AQ5: =DAY(hcp[[#This Row],[TGL_PEMBAYARAN]]) -> 3 | AR5: =TEXT(hcp[[#This Row],[TGL_PEMBAYARAN]],"YY-MM") -> 26-06 | AS5: =TEXT(hcp[[#This Row],[TANGGAL_BAYAR_ANGS_TERAKHIR]],"YY-MM") -> 26-05 | AT5: =IF(hcp[[#This Row],[Periode ( TANGGAL_BAYAR_ANGS_TERAKHIR )]]=hcp[[#This Row],[Periode ( TGL_PEMBAYARAN )]],"AKTIF","ALDA") -> ALDA | AU5: =hcp[[#This Row],[Periode ( TANGGAL_BAYAR_ANGS_TERAKHIR )]]=hcp[[#This Row],[Periode ( TGL_PEMBAYARAN )]] -> FALSE | AV5: =IF(hcp[[#This Row],[Tgl ( TGL_PEMBAYARAN )]]=DAY(TODAY()),1,0) -> 0
A6: Kalimantan | B6: 1004 | C6: Samarinda | D6: SAMARINDA | E6: 2W | F6: 1004210000323 | G6: MARISA | H6: 44363 | I6: 45307 | J6: SUZUKI | K6: NEX | L6: 2021 | M6: 082350561542 | N6: 085345767513 | O6: JL POROS SANGATTA BONTANG KM 40 RT 000 /RW 000, TELUK SINGKAMA, SANGATTA SELATAN, KUTAI TIMUR, 75683 | P6: DUSUN SANGKIMA RAYA RT 001 /RW 000, TELUK SINGKAMA, SANGATTA SELATAN, KUTAI TIMUR, 75683 | Q6: SANGATA RT 000 /RW 000, TELUK SINGKAMA, SANGATTA SELATAN, KUTAI TIMUR, 75683 | S6: 0 | T6: 2963750 | U6: 0 | V6: 2963750 | W6: 0 | X6: 2963750 | Y6: ICP | Z6: 2963750 | AA6: 46176 | AB6: 307000 | AC6: 307000 | AD6: WINPAY | AE6: 0 | AF6: 0 | AG6: 0 | AI6: On Hand | AK6: 0 | AL6: 0 | AM6: 2656750 | AN6: 2656750 | AO6: =VLOOKUP(hcp[[#This Row],[BRANCHID]],'New KC'!$A:$K,8,0) -> 05. Kalimantan | AP6: =VLOOKUP(hcp[[#This Row],[BRANCHID]],'New KC'!$A:$K,9,0) -> SAMARINDA | AQ6: =DAY(hcp[[#This Row],[TGL_PEMBAYARAN]]) -> 3 | AR6: =TEXT(hcp[[#This Row],[TGL_PEMBAYARAN]],"YY-MM") -> 26-06 | AS6: =TEXT(hcp[[#This Row],[TANGGAL_BAYAR_ANGS_TERAKHIR]],"YY-MM") -> 24-01 | AT6: =IF(hcp[[#This Row],[Periode ( TANGGAL_BAYAR_ANGS_TERAKHIR )]]=hcp[[#This Row],[Periode ( TGL_PEMBAYARAN )]],"AKTIF","ALDA") -> ALDA | AU6: =hcp[[#This Row],[Periode ( TANGGAL_BAYAR_ANGS_TERAKHIR )]]=hcp[[#This Row],[Periode ( TGL_PEMBAYARAN )]] -> FALSE | AV6: =IF(hcp[[#This Row],[Tgl ( TGL_PEMBAYARAN )]]=DAY(TODAY()),1,0) -> 0
A7: Kalimantan | B7: 1552 | C7: Sampit | D7: SAMPIT - MBL | E7: 4W | F7: 1552210000105 | G7: ELIZABETH BEKTI KURNIASARI | H7: 44345 | I7: 46174 | J7: SUZUKI | K7: KARIMUN WAGON R | L7: 2020 | M7: 082158016926 | O7: JL. JEND. SUDIRMAN NO.6 RT 011 /RW 000, SIDOREJO, ARUT SELATAN, KOTAWARINGIN BARAT, 74111 | P7: JL. JEND. SUDIRMAN NO.6 RT 011 /RW 000, SIDOREJO, ARUT SELATAN, KOTAWARINGIN BARAT, 74111 | Q7: JL. JEND. SUDIRMAN NO.6 RT 011 /RW 000, SIDOREJO, ARUT SELATAN, KOTAWARINGIN BARAT, 74111 | S7: 0 | T7: 0 | U7: 404955 | V7: 404955 | W7: 150000 | X7: 254955 | Y7: RRD | Z7: 0 | AA7: 46176 | AB7: 254955 | AC7: 0 | AD7: WINPAY | AE7: 0 | AF7: 0 | AG7: 0 | AH7: 46176 | AI7: On Hand | AK7: 0 | AL7: 0 | AM7: 150000 | AN7: 0 | AO7: =VLOOKUP(hcp[[#This Row],[BRANCHID]],'New KC'!$A:$K,8,0) -> 05. Kalimantan | AP7: =VLOOKUP(hcp[[#This Row],[BRANCHID]],'New KC'!$A:$K,9,0) -> SAMPIT | AQ7: =DAY(hcp[[#This Row],[TGL_PEMBAYARAN]]) -> 3 | AR7: =TEXT(hcp[[#This Row],[TGL_PEMBAYARAN]],"YY-MM") -> 26-06 | AS7: =TEXT(hcp[[#This Row],[TANGGAL_BAYAR_ANGS_TERAKHIR]],"YY-MM") -> 26-06 | AT7: =IF(hcp[[#This Row],[Periode ( TANGGAL_BAYAR_ANGS_TERAKHIR )]]=hcp[[#This Row],[Periode ( TGL_PEMBAYARAN )]],"AKTIF","ALDA") -> AKTIF | AU7: =hcp[[#This Row],[Periode ( TANGGAL_BAYAR_ANGS_TERAKHIR )]]=hcp[[#This Row],[Periode ( TGL_PEMBAYARAN )]] -> TRUE | AV7: =IF(hcp[[#This Row],[Tgl ( TGL_PEMBAYARAN )]]=DAY(TODAY()),1,0) -> 0
A8: Kalimantan | B8: 1552 | C8: Sampit | D8: SAMPIT - MBL | E8: 4W | F8: 1552220000091 | G8: GUSTI RAHMAT AHWAZAL MA RUF | H8: 44672 | I8: 46119 | J8: SUZUKI | K8: CARRY PU 1.5 | L8: 2022 | M8: 082252431203 | O8: JL. BEJI RT 005 /RW 000, KOTA WARINGIN HILIR, KOTAWARINGIN LAMA, KOTAWARINGIN BARAT, 74161 | P8: JL. BEJI RT 005 /RW 000, KOTA WARINGIN HILIR, KOTAWARINGIN LAMA, KOTAWARINGIN BARAT, 74161 | Q8: KOTAWARINGIN LAMA RT 000 /RW 000, KOTA WARINGIN HILIR, KOTAWARINGIN LAMA, KOTAWARINGIN BARAT, 74161 | S8: 0 | T8: 1403050 | U8: 0 | V8: 1403050 | W8: 0 | X8: 1403050 | Y8: ICP | Z8: 1403050 | AA8: 46176 | AB8: 1403050 | AC8: 1403050 | AD8: WINPAY | AE8: 0 | AF8: 0 | AG8: 0 | AI8: On Hand | AK8: 0 | AL8: 0 | AM8: 0 | AN8: 0 | AO8: =VLOOKUP(hcp[[#This Row],[BRANCHID]],'New KC'!$A:$K,8,0) -> 05. Kalimantan | AP8: =VLOOKUP(hcp[[#This Row],[BRANCHID]],'New KC'!$A:$K,9,0) -> SAMPIT | AQ8: =DAY(hcp[[#This Row],[TGL_PEMBAYARAN]]) -> 3 | AR8: =TEXT(hcp[[#This Row],[TGL_PEMBAYARAN]],"YY-MM") -> 26-06 | AS8: =TEXT(hcp[[#This Row],[TANGGAL_BAYAR_ANGS_TERAKHIR]],"YY-MM") -> 26-04 | AT8: =IF(hcp[[#This Row],[Periode ( TANGGAL_BAYAR_ANGS_TERAKHIR )]]=hcp[[#This Row],[Periode ( TGL_PEMBAYARAN )]],"AKTIF","ALDA") -> ALDA | AU8: =hcp[[#This Row],[Periode ( TANGGAL_BAYAR_ANGS_TERAKHIR )]]=hcp[[#This Row],[Periode ( TGL_PEMBAYARAN )]] -> FALSE | AV8: =IF(hcp[[#This Row],[Tgl ( TGL_PEMBAYARAN )]]=DAY(TODAY()),1,0) -> 0
A9: Sulawesi | B9: 1052 | C9: Kendari | D9: KENDARI | E9: 2W | F9: 1052190000460 | G9: MUSTAKIM | H9: 43809 | I9: 44925 | J9: SUZUKI | K9: GSX | L9: 2019 | M9: 082349572815 | O9: JL. LABUKU, KEL. ABELI, KEC. ABELI, KOTA KENDARI RT 03 /RW 02, ABELI, ABELI, KENDARI, 93234 | P9: JL. LABUKU, KEL. ABELI, KEC. ABELI, KOTA KENDARI RT 03 /RW 02, ABELI, ABELI, KENDARI, 93234 | Q9: ANDUONOHU MANDALA WALUYA JL JEND AHA NASUTION RT 00 /RW 00, KAMBU, KAMBU, KENDARI, 93231 | S9: 0 | T9: 1394780 | U9: 0 | V9: 1394780 | W9: 0 | X9: 1394780 | Y9: ICP | Z9: 1394780 | AA9: 46176 | AB9: 1394780 | AC9: 1394780 | AD9: WINPAY | AE9: 0 | AF9: 0 | AG9: 0 | AI9: On Hand | AK9: 0 | AL9: 0 | AM9: 0 | AN9: 0 | AO9: =VLOOKUP(hcp[[#This Row],[BRANCHID]],'New KC'!$A:$K,8,0) -> 06. Sulawesi | AP9: =VLOOKUP(hcp[[#This Row],[BRANCHID]],'New KC'!$A:$K,9,0) -> KENDARI | AQ9: =DAY(hcp[[#This Row],[TGL_PEMBAYARAN]]) -> 3 | AR9: =TEXT(hcp[[#This Row],[TGL_PEMBAYARAN]],"YY-MM") -> 26-06 | AS9: =TEXT(hcp[[#This Row],[TANGGAL_BAYAR_ANGS_TERAKHIR]],"YY-MM") -> 22-12 | AT9: =IF(hcp[[#This Row],[Periode ( TANGGAL_BAYAR_ANGS_TERAKHIR )]]=hcp[[#This Row],[Periode ( TGL_PEMBAYARAN )]],"AKTIF","ALDA") -> ALDA | AU9: =hcp[[#This Row],[Periode ( TANGGAL_BAYAR_ANGS_TERAKHIR )]]=hcp[[#This Row],[Periode ( TGL_PEMBAYARAN )]] -> FALSE | AV9: =IF(hcp[[#This Row],[Tgl ( TGL_PEMBAYARAN )]]=DAY(TODAY()),1,0) -> 0
