Workbook

Sheet KC
A1: BranchID | B1: BranchName | C1: BranchName- | D1: New Area | E1: Code | F1: New Area_Old | G1: BranchName_Old | H1: New Area_New | I1: BranchName_New | J1: Status | K1: Unit | M1: -10000 | N1: 0 | O1: 00.Not Ovd | P1: 00.Not OD | Q1: ARO
A2: 1001 | B2: BANJARMASIN | C2: BANJARMASIN | D2: 08. Kalselteng | E2: 2W | F2: 05. Kalimantan | G2: BANJARMASIN | H2: 05. Kalimantan | I2: BANJARMASIN | J2: BRANCH | K2: 1 | M2: 1 | N2: 30 | O2: 01.1-30 | P2: 01.1-30 | Q2: ARO
A3: 1002 | B3: MAKASAR | C3: MAKASAR | D3: 09. SulbagSel | E3: 2W | F3: 06. Sulawesi | G3: MAKASSAR | H3: 06. Sulawesi | I3: MAKASSAR | J3: BRANCH | K3: 1 | M3: 31 | N3: 60 | O3: 02.31-60 | P3: 02.31-60 | Q3: PSO
A4: 1003 | B4: BALIKPAPAN | C4: BALIKPAPAN | D4: 07. KalTimBar | E4: 2W | F4: 05. Kalimantan | G4: BALIKPAPAN | H4: 05. Kalimantan | I4: BALIKPAPAN | J4: BRANCH | K4: 1 | M4: 61 | N4: 90 | O4: 03.61-90 | P4: 03.61-90 | Q4: PSO
A5: 1004 | B5: SAMARINDA | C5: SAMARINDA | D5: 07. KalTimBar | E5: 2W | F5: 05. Kalimantan | G5: SAMARINDA | H5: 05. Kalimantan | I5: SAMARINDA | J5: BRANCH | K5: 1 | M5: 91 | N5: 120 | O5: 04.91-120 | P5: 04.91-120 | Q5: REMOFF
A6: 1005 | B6: BOGOR | C6: BOGOR | D6: 02. Jabotabek | E6: 2W | F6: 01. Jabodetabekser | G6: BOGOR | H6: 01. Jabodetabekser | I6: BOGOR | J6: BRANCH | K6: 1 | M6: 121 | N6: 150 | O6: 05.121-150 | P6: 05.121-150 | Q6: REMOFF
A7: 1006 | B7: BEKASI | C7: BEKASI | D7: 02. Jabotabek | E7: 2W | F7: 01. Jabodetabekser | G7: BEKASI | H7: 01. Jabodetabekser | I7: BEKASI | J7: BRANCH | K7: 1 | M7: 151 | N7: 180 | O7: 06.151-180 | P7: 06.151-180 | Q7: REMOFF
A8: 1007 | B8: KEDIRI | C8: KEDIRI | D8: 05. JatimSel | E8: 2W | F8: 04. Jawa Timur | G8: KEDIRI | H8: 04. Jawa Timur | I8: KEDIRI | J8: BRANCH | K8: 1 | M8: 181 | N8: 10000000 | O8: 07.>180 | P8: 07.>180 | Q8: PC
A9: 1008 | B9: KARAWANG | C9: KARAWANG | D9: 01. Jabar | E9: 2W | F9: 02. Jawa Barat | G9: KARAWANG | H9: 02. Jawa Barat | I9: KARAWANG | J9: BRANCH | K9: 1
A10: 1009 | B10: MADIUN | C10: MADIUN | D10: 06. JatimUt | E10: 2W | F10: 04. Jawa Timur | G10: KEDIRI | H10: 04. Jawa Timur | I10: KEDIRI | J10: DCSM MIX | K10: 1
A11: 1010 | B11: MEDAN | C11: MEDAN | D11: 13. SumbagUt | E11: 2W | F11: 08. Sumbaguteng | G11: MEDAN | H11: 08. Sumbaguteng | I11: MEDAN | J11: BRANCH | K11: 1
A12: 1011 | B12: KELAPA GADING | C12: KELAPA GADING | D12: 02. Jabotabek | E12: 2W | F12: 01. Jabodetabekser | G12: KELAPA GADING / SUNTER | H12: 01. Jabodetabekser | I12: SUNTER | J12: BRANCH | K12: 1
A13: 1012 | B13: BANDUNG | C13: BANDUNG | D13: 01. Jabar | E13: 2W | F13: 02. Jawa Barat | G13: BANDUNG | H13: 02. Jawa Barat | I13: BANDUNG | J13: BRANCH | K13: 1
A14: 1013 | B14: YOGYA | C14: YOGYA | D14: 03. JatengSel | E14: 2W | F14: 03. Jawa Tengah | G14: YOGYAKARTA | H14: 03. Jawa Tengah | I14: YOGYAKARTA | J14: BRANCH | K14: 1
A15: 1014 | B15: SOLO | C15: SOLO | D15: 03. JatengSel | E15: 2W | F15: 03. Jawa Tengah | G15: SOLO | H15: 03. Jawa Tengah | I15: SOLO | J15: BRANCH | K15: 1
A16: 1015 | B16: SEMARANG | C16: SEMARANG | D16: 04. Jatengut | E16: 2W | F16: 03. Jawa Tengah | G16: SEMARANG | H16: 03. Jawa Tengah | I16: SEMARANG | J16: BRANCH | K16: 1
A17: 1016 | B17: SURABAYA | C17: SURABAYA | D17: 06. JatimUt | E17: 2W | F17: 04. Jawa Timur | G17: SURABAYA | H17: 04. Jawa Timur | I17: SURABAYA | J17: BRANCH | K17: 1
A18: 1017 | B18: MALANG | C18: MALANG | D18: 05. JatimSel | E18: 2W | F18: 04. Jawa Timur | G18: MALANG | H18: 04. Jawa Timur | I18: MALANG | J18: BRANCH | K18: 1
A19: 1018 | B19: SIDOARJO | C19: SIDOARJO | D19: 06. JatimUt | E19: 2W | F19: 04. Jawa Timur | G19: SURABAYA | H19: 04. Jawa Timur | I19: SURABAYA | J19: DCSM MIX | K19: 1
A20: 1019 | B20: GRESIK | C20: GRESIK | D20: 06. JatimUt | E20: 2W | F20: 04. Jawa Timur | G20: GRESIK | H20: 04. Jawa Timur | I20: GRESIK | J20: BRANCH | K20: 1
... A84: 1082 | B84: UJUNG BATU | C84: PEKAN BARU | D84: 12. SumbagTeng | E84: 2W | F84: 08. Sumbaguteng | G84: PEKANBARU | H84: 08. Sumbaguteng | I84: PEKANBARU | J84: BRANCH | K84: 1
A85: 1083 | B85: LUBUK LINGGAU | C85: PALEMBANG | D85: 11. SumbagSel | E85: 2W | F85: 07. Sumbagsel | G85: BENGKULU | H85: 07. Sumbagsel | I85: PALEMBANG | J85: BRANCH | K85: 1 | L85: PALEMBANG 1-4
A86: 1086 | B86: MAKASSAR 2 | C86: MAKASAR | D86: 09. SulbagSel | E86: 2W | F86: 06. Sulawesi | G86: MAKASSAR | H86: 06. Sulawesi | I86: MAKASSAR | J86: BRANCH | K86: 1
A87: 1087 | B87: SAMPIT | C87: SAMPIT | D87: 08. Kalselteng | E87: 2W | F87: 05. Kalimantan | G87: SAMPIT | H87: 05. Kalimantan | I87: SAMPIT | J87: BRANCH | K87: 1
A88: 1088 | B88: BANDAR JAYA | C88: BANDAR JAYA | D88: 11. SumbagSel | E88: 2W | F88: 07. Sumbagsel | G88: BANDAR LAMPUNG | H88: 07. Sumbagsel | I88: BANDAR LAMPUNG | J88: DCSM MIX | K88: 1
A89: 1089 | B89: KUPANG | C89: KUPANG | D89: 14. IBT | E89: 2W | F89: 09. IBT | G89: KUPANG | H89: 09. IBT | I89: KUPANG | J89: BRANCH | K89: 1
A90: 1090 | B90: BUKITTINGGI | C90: PADANG | D90: 12. SumbagTeng | E90: 2W | F90: 08. Sumbaguteng | G90: PADANG | H90: 08. Sumbaguteng | I90: PEKANBARU | J90: BRANCH | K90: 1
A91: 1094 | B91: MEDAN 2 | C91: MEDAN | D91: 13. SumbagUt | E91: 2W | F91: 08. Sumbaguteng | G91: MEDAN | H91: 08. Sumbaguteng | I91: MEDAN | J91: BRANCH | K91: 1
A92: 1095 | B92: MEDAN 3 | C92: MEDAN | D92: 13. SumbagUt | E92: 2W | F92: 08. Sumbaguteng | G92: MEDAN | H92: 08. Sumbaguteng | I92: MEDAN | J92: BRANCH | K92: 1
A93: 1301 | B93: BANJARMASIN Syariah | C93: BANJARMASIN | D93: 08. Kalselteng | E93: 2W | F93: 05. Kalimantan | G93: BANJARMASIN | H93: 05. Kalimantan | I93: BANJARMASIN | J93: BRANCH | K93: 1
A94: 1302 | B94: MAKASAR Syariah | C94: MAKASAR | D94: 09. SulbagSel | E94: 2W | F94: 06. Sulawesi | G94: MAKASSAR | H94: 06. Sulawesi | I94: MAKASSAR | J94: BRANCH | K94: 1
A95: 1303 | B95: BALIKPAPAN Syariah | C95: BALIKPAPAN | D95: 07. KalTimBar | E95: 2W | F95: 05. Kalimantan | G95: BALIKPAPAN | H95: 05. Kalimantan | I95: BALIKPAPAN | J95: BRANCH | K95: 1
A96: 1304 | B96: SAMARINDA Syariah | C96: SAMARINDA | D96: 07. KalTimBar | E96: 2W | F96: 05. Kalimantan | G96: SAMARINDA | H96: 05. Kalimantan | I96: SAMARINDA | J96: BRANCH | K96: 1
A97: 1305 | B97: BOGOR Syariah | C97: BOGOR | D97: 02. Jabotabek | E97: 2W | F97: 01. Jabodetabekser | G97: BOGOR | H97: 01. Jabodetabekser | I97: BOGOR | J97: BRANCH | K97: 1
... A219: 1039 | B219: BAWEN | C219: SEMARANG | D219: 04. Jatengut | E219: 2W | F219: 03. Jawa Tengah | G219: SEMARANG | H219: 03. Jawa Tengah | I219: SEMARANG | J219: BRANCH | K219: 1
A220: 1801 | B220: OBM - SFI KANTOR PUSAT | C220: =B220 -> OBM - SFI KANTOR PUSAT | D220: 15. OBM | E220: OBM | F220: 10. OBM | G220: =C220 -> OBM - SFI KANTOR PUSAT | H220: 01. Jabodetabekser | I220: SUNTER | J220: HO | K220: 1
A221: 1802 | B221: OBM - DENPASAR | C221: =B221 -> OBM - DENPASAR | D221: 15. OBM | E221: OBM | F221: 10. OBM | G221: =C221 -> OBM - DENPASAR | H221: 09. IBT | I221: DENPASAR | J221: BRANCH | K221: 1
A222: 1803 | B222: OBM - MANADO | C222: =B222 -> OBM - MANADO | D222: 15. OBM | E222: OBM | F222: 10. OBM | G222: =C222 -> OBM - MANADO | H222: 06. Sulawesi | I222: MANADO | J222: BRANCH | K222: 1
A223: 1000 | B223: FATMAWATI - MBL | C223: FATMAWATI - MBL | D223: 02. Jakarta 2 | E223: 2W | F223: 01. Jabodetabekser | G223: DEWI SARTIKA | H223: 01. Jabodetabekser | I223: DEWI SARTIKA | J223: BRANCH | K223: 1
A224: 1804 | B224: OBM - BALIKPAPAN | C224: =B224 -> OBM - BALIKPAPAN | D224: 15. OBM | E224: OBM | F224: 10. OBM | G224: =C224 -> OBM - BALIKPAPAN | H224: 05. Kalimantan | I224: BALIKPAPAN | J224: BRANCH | K224: 1
...

Sheet CWO Bulan Lalu
A1: BranchID | B1: BranchName | C1: Transdate | D1: TglJatuhTempo | E1: TglPPD | F1: CustomerID | G1: ContractID | H1: NamaCustomer | I1: Alamat | J1: KodePos | K1: SubZipCode | L1: KodePos2 | M1: Kelurahan | N1: Kecamatan | O1: Kota | P1: KodeDCS | Q1: NamaDCS | R1: GroupID | S1: NamaCustomerGroup | T1: TlpRumah | U1: TlpKantor | V1: MobilePhone | W1: ObjectDesc | X1: BrandDesc | Y1: TypeDesc1 | Z1: TypeDesc2 | AA1: RangkaNumber | AB1: EngineNumber | AC1: PoliceNumber | AD1: OtsBalance | AE1: OtsPokok | AF1: NYD | AG1: AMOVD | AH1: Denda | AI1: Titipan | AJ1: Installment | AK1: DaysOD | AL1: JumlahAngsuranOD | AM1: SequenceID | AN1: CreditPeriod | AO1: OD1 | AP1: OD2 | AQ1: OD3 | AR1: CollectorID | AS1: CollectorNIK | AT1: PIC | AU1: CoordinatorID | AV1: CoordinatorNIK | AW1: Coordinator | AX1: CoordPost | AY1: HeadID | AZ1: HeadNIK | BA1: Head | BB1: HeadPost | BC1: CHID | BD1: CHNIK | BE1: CH | BF1: CHPost | BG1: Status | BH1: InstDue | BI1: InstDueRp | BJ1: TglTebus | BK1: TglTarik | BL1: TglProsesAsr | BM1: PrevPIC | BN1: EndDateProcess | BO1: Unit | BP1: RunningReportDate | BQ1: DailyCollectibility | BR1: OvdDaysHarian | BS1: TglJatuhTempoHarian | BT1: EAR | BU1: ARIN | BV1: FlowUp | BW1: PaidOff | BX1: RR | BY1: InstPaidReal | BZ1: InstPaid | CA1: InstPaidRealRp | CB1: InstPaidRp | CC1: TglTarikHarian | CD1: Ditarik | CE1: TglTebusHarian | CF1: Ditebus | CG1: TglInvHarian | CH1: ADP | CI1: TglProses AsrHarian | CJ1: ProsesAsrHarian | CK1: TglTerimaKlaim | CL1: KlaimAsr | CM1: Period | CN1: Product | CO1: Amount_CWO | CP1: Amount_WO | CQ1: Hari_WO | CR1: Tanggal_Sukses | CS1: Keterangan_Sukses | CT1: Success_Amt | CU1: BranchName- | CV1: New Area | CW1: reportDate | CX1: DataPeriod | CY1: MONTH | CZ1: Tgl WO-in | DA1: CWO Amt | DB1: Success CWO | DC1: Success CWO Amt | DD1: WO-In-Amt | DE1: Tgl Success | DF1: Potensi WO | DG1: Potensi WO-Amt | DH1: Portfolio | DI1: Area | DJ1: Cabang | DK1: Tanggal_Sukses-new | DL1: Keterangan_Sukses-new
A2: 1529 | B2: BALIKPAPAN | C2: 46142 | D2: 45988 | E2: 44953 | F2: 1529C20230100053 | G2: 1529230000019 | H2: PARIS | I2: JL. PADAT KARYA RT 003 RW 001 Kel.Sebidai Kec. Sesayap Kota Kab. Tana Tidung 77152 | J2: 77152 | L2: 77152 | M2: Sebidai | N2: Sesayap | O2: Kab. Tana Tidung | P2: 15290005 | Q2: Bulungan | T2: 5120**** | U2: 5120**** | V2: 08135******* | W2: MOBIL Baru | X2: SUZUKI | Y2: CARRY PU 1.5 | Z2: NEW CARRY PU FD AC PS | AA2: MHYHDC61TNJ264912 | AB2: K15BT1482440 | AC2: KU 8155 HB | AD2: 117531000 | AE2: 95237329 | AF2: 91413000 | AG2: 26118000 | AH2: 17903876 | AI2: 216000 | AJ2: 4353000 | AK2: 154 | AL2: 6 | AM2: 34 | AN2: 60 | AO2: 06.151-180 | AP2: 06.151-180 | AQ2: 03.RO | AR2: 160007 | AS2: 20251024356 | AT2: SUPRIYANTO | AU2: 1529ARC003 | AV2: 00000000000 | AW2: TIDAK ADA | AX2: RMC | AY2: 159154 | AZ2: 20250424231 | BA2: ALEX SANDRA | BB2: RMH | BC2: 1529CH003 | BD2: 20171100044 | BE2: TDK ADA | BF2: Coll-Head | BG2: PU-WC | BH2: 7 | BI2: 30471000 | BK2: 46139 | BN2: 46173 | BO2: 1 | BP2: 46149 | BQ2: Coll Harian | BR2: 161 | BS2: 45988 | BT2: 117531000 | BU2: 0 | BV2: 1 | BW2: 0 | BX2: 0 | BY2: 0 | BZ2: 0 | CA2: 0 | CB2: 0 | CD2: 0 | CF2: 0 | CH2: 0 | CJ2: 0 | CL2: 0 | CM2: 46149 | CN2: 4W | CO2: 95021329 | CP2: 0 | CQ2: 0 | CR2: 46139 | CS2: REPO SEBELUM WO | CT2: 95021329 | CU2: BALIKPAPAN - MBL | CV2: 09. Kalimantan | CW2: 46149 | CX2: Last Month | CY2: =MONTH(Table_ExternalData_14[[#This Row],[RunningReportDate]]) -> 5 | CZ2: =181-Table_ExternalData_14[[#This Row],[DaysOD]] -> 27 | DA2: =IF(Table_ExternalData_14[[#This Row],[Status]]="PU-WC",0,Table_ExternalData_14[[#This Row],[Amount_CWO]]/1000000) -> 0 | DB2: =IF(Table_ExternalData_14[[#This Row],[Status]]="PU-WC",0,IF(Table_ExternalData_14[[#This Row],[Keterangan_Sukses-new]]="RB",1,IF(Table_ExternalData_14[[#This Row],[Keterangan_Sukses-new]]="STAY",1,IF(Table_ExternalData_14[[#This Row],[Keterangan_Sukses-new]]="BTC",1,IF(ISERROR(FIND("SEBELUM",Table_ExternalData_14[[#This Row],[Keterangan_Sukses-new]],1)),0,1))))) -> 0 | DC2: =IF(Table_ExternalData_14[[#This Row],[Status]]="PU-WC",0,IF(Table_ExternalData_14[[#This Row],[Success CWO]]=1,Table_ExternalData_14[[#This Row],[CWO Amt]],0)) -> 0 | DD2: =IF(AND(Table_ExternalData_14[[#This Row],[Status]]="InsuranceClaim",Table_ExternalData_14[[#This Row],[TglTarik]]>0),0,IF(Table_ExternalData_14[[#This Row],[ContractID]]="1547220000067",0,IF(Table_ExternalData_14[[#This Row],[Status]]="PU-WC",0,IF(Table_ExternalData_14[[#This Row],[Tgl WO-in]]<= DAY(Table_ExternalData_14[[#This Row],[Period]]),Table_ExternalData_14[[#This Row],[Amount_WO]]/1000000,0)))) -> 0 | DE2: =DAY(Table_ExternalData_14[[#This Row],[Tanggal_Sukses-new]]) -> 27 | DF2: =IF(Table_ExternalData_14[[#This Row],[Status]]="PU-WC",0,IF(SUM(Table_ExternalData_14[[#This Row],[Success CWO]:[WO-In-Amt]])=0,1,0)) -> 0 | DG2: =IF(AND(Table_ExternalData_14[[#This Row],[Status]]="InsuranceClaim",Table_ExternalData_14[[#This Row],[TglTarik]]>0),0,IF(Table_ExternalData_14[[#This Row],[Status]]="PU-WC",0,IF(Table_ExternalData_14[[#This Row],[Potensi WO]]=1,Table_ExternalData_14[[#This Row],[CWO Amt]],0))) -> 0 | DH2: =VLOOKUP(Table_ExternalData_14[[#This Row],[BranchID]],KC!$A:$K,5,0) -> 4W | DI2: =VLOOKUP(Table_ExternalData_14[[#This Row],[BranchID]],KC!$A:$K,8,0) -> 05. Kalimantan | DJ2: =VLOOKUP(Table_ExternalData_14[[#This Row],[BranchID]],KC!$A:$K,9,0) -> BALIKPAPAN | DK2: =IF(Table_ExternalData_14[[#This Row],[Tanggal_Sukses]]=" ",Table_ExternalData_14[[#This Row],[Tanggal_Sukses]],VLOOKUP(Table_ExternalData_14[[#This Row],[ContractID]],Bantuan!$A:$C,2,0)) -> 46139 | DL2: =IF(Table_ExternalData_14[[#This Row],[Keterangan_Sukses]]=" ",Table_ExternalData_14[[#This Row],[Keterangan_Sukses]],VLOOKUP(Table_ExternalData_14[[#This Row],[ContractID]],Bantuan!$A:$C,3,0)) -> REPO SEBELUM WO
A3: 1529 | B3: BALIKPAPAN | C3: 46142 | D3: 45981 | E3: 45250 | F3: 1529C20231100053 | G3: 1529230000402 | H3: MUHAMMAD LUKMAN | I3: JL. SLAMET RIYADI RT 005 RW 003 Kel.TIDENG PALE Kec. SESAYAP Kota TANA TIDUNG 77152 | J3: 77152 | L3: 77152 | M3: TIDENG PALE | N3: SESAYAP | O3: TANA TIDUNG | P3: 15290005 | Q3: Bulungan | T3: 5011**** | U3: 5011**** | V3: 08235******* | W3: MOBIL Baru | X3: SUZUKI | Y3: CARRY PU 1.5 | Z3: NEW CARRY PU FD AC PS | AA3: MHYHDC61TPJ213438 | AB3: K15BT1498478 | AC3: KU 8218 HB | AD3: 172050000 | AE3: 1.2737553e+08 | AF3: 144150000 | AG3: 27900000 | AH3: 41593000 | AI3: 2040000 | AJ3: 4650000 | AK3: 161 | AL3: 6 | AM3: 24 | AN3: 60 | AO3: 06.151-180 | AP3: 06.151-180 | AQ3: 03.RO | AR3: 160007 | AS3: 20251024356 | AT3: SUPRIYANTO | AU3: 1529ARC003 | AV3: 00000000000 | AW3: TIDAK ADA | AX3: RMC | AY3: 159154 | AZ3: 20250424231 | BA3: ALEX SANDRA | BB3: RMH | BC3: 1529CH003 | BD3: 20171100044 | BE3: TDK ADA | BF3: Coll-Head | BG3: PU-WC | BH3: 7 | BI3: 32550000 | BK3: 46134 | BN3: 46173 | BO3: 1 | BP3: 46149 | BQ3: Coll Harian | BR3: 168 | BS3: 45981 | BT3: 172050000 | BU3: 0 | BV3: 1 | BW3: 0 | BX3: 0 | BY3: 0 | BZ3: 0 | CA3: 0 | CB3: 0 | CD3: 0 | CF3: 0 | CH3: 0 | CJ3: 0 | CL3: 0 | CM3: 46149 | CN3: 4W | CO3: 1.2533553e+08 | CP3: 0 | CQ3: 0 | CR3: 46134 | CS3: REPO SEBELUM WO | CT3: 1.2533553e+08 | CU3: BALIKPAPAN - MBL | CV3: 09. Kalimantan | CW3: 46149 | CX3: Last Month | CY3: =MONTH(Table_ExternalData_14[[#This Row],[RunningReportDate]]) -> 5 | CZ3: =181-Table_ExternalData_14[[#This Row],[DaysOD]] -> 20 | DA3: =IF(Table_ExternalData_14[[#This Row],[Status]]="PU-WC",0,Table_ExternalData_14[[#This Row],[Amount_CWO]]/1000000) -> 0 | DB3: =IF(Table_ExternalData_14[[#This Row],[Status]]="PU-WC",0,IF(Table_ExternalData_14[[#This Row],[Keterangan_Sukses-new]]="RB",1,IF(Table_ExternalData_14[[#This Row],[Keterangan_Sukses-new]]="STAY",1,IF(Table_ExternalData_14[[#This Row],[Keterangan_Sukses-new]]="BTC",1,IF(ISERROR(FIND("SEBELUM",Table_ExternalData_14[[#This Row],[Keterangan_Sukses-new]],1)),0,1))))) -> 0 | DC3: =IF(Table_ExternalData_14[[#This Row],[Status]]="PU-WC",0,IF(Table_ExternalData_14[[#This Row],[Success CWO]]=1,Table_ExternalData_14[[#This Row],[CWO Amt]],0)) -> 0 | DD3: =IF(AND(Table_ExternalData_14[[#This Row],[Status]]="InsuranceClaim",Table_ExternalData_14[[#This Row],[TglTarik]]>0),0,IF(Table_ExternalData_14[[#This Row],[ContractID]]="1547220000067",0,IF(Table_ExternalData_14[[#This Row],[Status]]="PU-WC",0,IF(Table_ExternalData_14[[#This Row],[Tgl WO-in]]<= DAY(Table_ExternalData_14[[#This Row],[Period]]),Table_ExternalData_14[[#This Row],[Amount_WO]]/1000000,0)))) -> 0 | DE3: =DAY(Table_ExternalData_14[[#This Row],[Tanggal_Sukses-new]]) -> 22 | DF3: =IF(Table_ExternalData_14[[#This Row],[Status]]="PU-WC",0,IF(SUM(Table_ExternalData_14[[#This Row],[Success CWO]:[WO-In-Amt]])=0,1,0)) -> 0 | DG3: =IF(AND(Table_ExternalData_14[[#This Row],[Status]]="InsuranceClaim",Table_ExternalData_14[[#This Row],[TglTarik]]>0),0,IF(Table_ExternalData_14[[#This Row],[Status]]="PU-WC",0,IF(Table_ExternalData_14[[#This Row],[Potensi WO]]=1,Table_ExternalData_14[[#This Row],[CWO Amt]],0))) -> 0 | DH3: =VLOOKUP(Table_ExternalData_14[[#This Row],[BranchID]],KC!$A:$K,5,0) -> 4W | DI3: =VLOOKUP(Table_ExternalData_14[[#This Row],[BranchID]],KC!$A:$K,8,0) -> 05. Kalimantan | DJ3: =VLOOKUP(Table_ExternalData_14[[#This Row],[BranchID]],KC!$A:$K,9,0) -> BALIKPAPAN | DK3: =IF(Table_ExternalData_14[[#This Row],[Tanggal_Sukses]]=" ",Table_ExternalData_14[[#This Row],[Tanggal_Sukses]],VLOOKUP(Table_ExternalData_14[[#This Row],[ContractID]],Bantuan!$A:$C,2,0)) -> 46134 | DL3: =IF(Table_ExternalData_14[[#This Row],[Keterangan_Sukses]]=" ",Table_ExternalData_14[[#This Row],[Keterangan_Sukses]],VLOOKUP(Table_ExternalData_14[[#This Row],[ContractID]],Bantuan!$A:$C,3,0)) -> REPO SEBELUM WO
A4: 1529 | B4: BALIKPAPAN | C4: 46142 | D4: 45966 | E4: 45808 | F4: 1529C20250500042 | G4: 1529250000108 | H4: SYAHRIL HADI SAPUTRA | I4: SEBAKUNG RT 001 RW 000 Kel.SEBAKUNG Kec. LONG KALI Kota PASER 76283 | J4: 76283 | L4: 76283 | M4: SEBAKUNG | N4: LONG KALI | O4: PASER | P4: 15290001 | Q4: Balikpapan | T4: 8777**** | U4: 8777**** | V4: 08538******* | W4: MOBIL Baru | X4: SUZUKI | Y4: CARRY PU 1.5 | Z4: NEW CARRY PU FD | AA4: MHYHDC61TRJ271397 | AB4: K15BT1653631 | AC4: KT 8019 ET | AD4: 209484000 | AE4: 1.5003221e+08 | AF4: 180918000 | AG4: 28566000 | AH4: 15230420 | AI4: 0 | AJ4: 4761000 | AK4: 176 | AL4: 6 | AM4: 5 | AN4: 48 | AO4: 06.151-180 | AP4: 06.151-180 | AQ4: 03.RO | AR4: 148436 | AS4: 20060802192 | AT4: JONI SUSONO | AU4: 1529ARC003 | AV4: 00000000000 | AW4: TIDAK ADA | AX4: RMC | AY4: 159772 | AZ4: 20080905969 | BA4: EDI JUNIANTO | BB4: RMH | BC4: 1529CH003 | BD4: 20171100044 | BE4: TDK ADA | BF4: Coll-Head | BG4: Collectible | BH4: 7 | BI4: 33327000 | BN4: 46173 | BO4: 1 | BP4: 46149 | BQ4: Coll Harian | BR4: 183 | BS4: 45966 | BT4: 209484000 | BU4: 0 | BV4: 1 | BW4: 0 | BX4: 0 | BY4: 0 | BZ4: 0 | CA4: 0 | CB4: 0 | CD4: 0 | CF4: 0 | CH4: 0 | CJ4: 0 | CL4: 0 | CM4: 46149 | CN4: 4W | CO4: 1.5003221e+08 | CP4: 1.5003221e+08 | CQ4: 5 | CT4: 0 | CU4: BALIKPAPAN - MBL | CV4: 09. Kalimantan | CW4: 46149 | CX4: Last Month | CY4: =MONTH(Table_ExternalData_14[[#This Row],[RunningReportDate]]) -> 5 | CZ4: =181-Table_ExternalData_14[[#This Row],[DaysOD]] -> 5 | DA4: =IF(Table_ExternalData_14[[#This Row],[Status]]="PU-WC",0,Table_ExternalData_14[[#This Row],[Amount_CWO]]/1000000) -> 150.03221 | DB4: =IF(Table_ExternalData_14[[#This Row],[Status]]="PU-WC",0,IF(Table_ExternalData_14[[#This Row],[Keterangan_Sukses-new]]="RB",1,IF(Table_ExternalData_14[[#This Row],[Keterangan_Sukses-new]]="STAY",1,IF(Table_ExternalData_14[[#This Row],[Keterangan_Sukses-new]]="BTC",1,IF(ISERROR(FIND("SEBELUM",Table_ExternalData_14[[#This Row],[Keterangan_Sukses-new]],1)),0,1))))) -> 0 | DC4: =IF(Table_ExternalData_14[[#This Row],[Status]]="PU-WC",0,IF(Table_ExternalData_14[[#This Row],[Success CWO]]=1,Table_ExternalData_14[[#This Row],[CWO Amt]],0)) -> 0 | DD4: =IF(AND(Table_ExternalData_14[[#This Row],[Status]]="InsuranceClaim",Table_ExternalData_14[[#This Row],[TglTarik]]>0),0,IF(Table_ExternalData_14[[#This Row],[ContractID]]="1547220000067",0,IF(Table_ExternalData_14[[#This Row],[Status]]="PU-WC",0,IF(Table_ExternalData_14[[#This Row],[Tgl WO-in]]<= DAY(Table_ExternalData_14[[#This Row],[Period]]),Table_ExternalData_14[[#This Row],[Amount_WO]]/1000000,0)))) -> 150.03221 | DE4: =DAY(Table_ExternalData_14[[#This Row],[Tanggal_Sukses-new]]) -> 0 | DF4: =IF(Table_ExternalData_14[[#This Row],[Status]]="PU-WC",0,IF(SUM(Table_ExternalData_14[[#This Row],[Success CWO]:[WO-In-Amt]])=0,1,0)) -> 0 | DG4: =IF(AND(Table_ExternalData_14[[#This Row],[Status]]="InsuranceClaim",Table_ExternalData_14[[#This Row],[TglTarik]]>0),0,IF(Table_ExternalData_14[[#This Row],[Status]]="PU-WC",0,IF(Table_ExternalData_14[[#This Row],[Potensi WO]]=1,Table_ExternalData_14[[#This Row],[CWO Amt]],0))) -> 0 | DH4: =VLOOKUP(Table_ExternalData_14[[#This Row],[BranchID]],KC!$A:$K,5,0) -> 4W | DI4: =VLOOKUP(Table_ExternalData_14[[#This Row],[BranchID]],KC!$A:$K,8,0) -> 05. Kalimantan | DJ4: =VLOOKUP(Table_ExternalData_14[[#This Row],[BranchID]],KC!$A:$K,9,0) -> BALIKPAPAN | DK4: =IF(Table_ExternalData_14[[#This Row],[Tanggal_Sukses]]=" ",Table_ExternalData_14[[#This Row],[Tanggal_Sukses]],VLOOKUP(Table_ExternalData_14[[#This Row],[ContractID]],Bantuan!$A:$C,2,0)) -> 0 | DL4: =IF(Table_ExternalData_14[[#This Row],[Keterangan_Sukses]]=" ",Table_ExternalData_14[[#This Row],[Keterangan_Sukses]],VLOOKUP(Table_ExternalData_14[[#This Row],[ContractID]],Bantuan!$A:$C,3,0)) -> 0
A5: 1531 | B5: KUPANG | C5: 46142 | D5: 45980 | E5: 44400 | F5: 1531C20200600135 | G5: 1531210000162 | H5: VICTOR IMANUEL LAY | I5: LELOGAMA RT 009 RW 005 Kel.LELOGAMA Kec. AMFOANG SELATAN Kota KUPANG 85364 | J5: 85364 | L5: 85364 | M5: LELOGAMA | N5: AMFOANG SELATAN | O5: KUPANG | P5: 15310000 | Q5: Kupang | T5: 0 | U5: 0 | V5: 08133******* | W5: MOBIL Baru | X5: SUZUKI | Y5: CARRY PU 1.5 | Z5: NEW CARRY PU FD | AA5: MHYHDC61TMJ229294 | AB5: K15BT1273332 | AC5: DH 8945 BF | AD5: 4557000 | AE5: 4496825.7 | AF5: 0 | AG5: 4557000 | AH5: 39806355 | AI5: 49607.5 | AJ5: 4557000 | AK5: 162 | AL5: 1 | AM5: 51 | AN5: 51 | AO5: 06.151-180 | AP5: 06.151-180 | AQ5: 03.RO | AR5: 1531REM59 | AS5: 20230923758 | AT5: NOVENTIO CORNEL LUDJI | AU5: 1531ARC01 | AV5: 00000000000 | AW5: TIDAK ADA | AX5: RMC | AY5: 1531ARHEAD | AZ5: 20111111728 | BA5: DONALD E DALLY | BB5: RMH | BC5: 1531CH01 | BD5: 00000000000 | BE5: TIDAK ADA | BF5: Coll-Head | BG5: Collectible | BH5: 1 | BI5: 4557000 | BN5: 46173 | BO5: 1 | BP5: 46149 | BQ5: Coll Harian | BR5: 169 | BS5: 45980 | BT5: 4557000 | BU5: 0 | BV5: 1 | BW5: 0 | BX5: 0 | BY5: 0 | BZ5: 0 | CA5: 0 | CB5: 0 | CD5: 0 | CF5: 0 | CH5: 0 | CJ5: 0 | CL5: 0 | CM5: 46149 | CN5: 4W | CO5: 4447218.2 | CP5: 4447218.2 | CQ5: 19 | CT5: 0 | CU5: KUPANG - MBL | CV5: 11. Bali & Nusa Tenggara | CW5: 46149 | CX5: Last Month | CY5: =MONTH(Table_ExternalData_14[[#This Row],[RunningReportDate]]) -> 5 | CZ5: =181-Table_ExternalData_14[[#This Row],[DaysOD]] -> 19 | DA5: =IF(Table_ExternalData_14[[#This Row],[Status]]="PU-WC",0,Table_ExternalData_14[[#This Row],[Amount_CWO]]/1000000) -> 4.4472182 | DB5: =IF(Table_ExternalData_14[[#This Row],[Status]]="PU-WC",0,IF(Table_ExternalData_14[[#This Row],[Keterangan_Sukses-new]]="RB",1,IF(Table_ExternalData_14[[#This Row],[Keterangan_Sukses-new]]="STAY",1,IF(Table_ExternalData_14[[#This Row],[Keterangan_Sukses-new]]="BTC",1,IF(ISERROR(FIND("SEBELUM",Table_ExternalData_14[[#This Row],[Keterangan_Sukses-new]],1)),0,1))))) -> 0 | DC5: =IF(Table_ExternalData_14[[#This Row],[Status]]="PU-WC",0,IF(Table_ExternalData_14[[#This Row],[Success CWO]]=1,Table_ExternalData_14[[#This Row],[CWO Amt]],0)) -> 0 | DD5: =IF(AND(Table_ExternalData_14[[#This Row],[Status]]="InsuranceClaim",Table_ExternalData_14[[#This Row],[TglTarik]]>0),0,IF(Table_ExternalData_14[[#This Row],[ContractID]]="1547220000067",0,IF(Table_ExternalData_14[[#This Row],[Status]]="PU-WC",0,IF(Table_ExternalData_14[[#This Row],[Tgl WO-in]]<= DAY(Table_ExternalData_14[[#This Row],[Period]]),Table_ExternalData_14[[#This Row],[Amount_WO]]/1000000,0)))) -> 0 | DE5: =DAY(Table_ExternalData_14[[#This Row],[Tanggal_Sukses-new]]) -> 0 | DF5: =IF(Table_ExternalData_14[[#This Row],[Status]]="PU-WC",0,IF(SUM(Table_ExternalData_14[[#This Row],[Success CWO]:[WO-In-Amt]])=0,1,0)) -> 1 | DG5: =IF(AND(Table_ExternalData_14[[#This Row],[Status]]="InsuranceClaim",Table_ExternalData_14[[#This Row],[TglTarik]]>0),0,IF(Table_ExternalData_14[[#This Row],[Status]]="PU-WC",0,IF(Table_ExternalData_14[[#This Row],[Potensi WO]]=1,Table_ExternalData_14[[#This Row],[CWO Amt]],0))) -> 4.4472182 | DH5: =VLOOKUP(Table_ExternalData_14[[#This Row],[BranchID]],KC!$A:$K,5,0) -> 4W | DI5: =VLOOKUP(Table_ExternalData_14[[#This Row],[BranchID]],KC!$A:$K,8,0) -> 09. IBT | DJ5: =VLOOKUP(Table_ExternalData_14[[#This Row],[BranchID]],KC!$A:$K,9,0) -> KUPANG | DK5: =IF(Table_ExternalData_14[[#This Row],[Tanggal_Sukses]]=" ",Table_ExternalData_14[[#This Row],[Tanggal_Sukses]],VLOOKUP(Table_ExternalData_14[[#This Row],[ContractID]],Bantuan!$A:$C,2,0)) -> 0 | DL5: =IF(Table_ExternalData_14[[#This Row],[Keterangan_Sukses]]=" ",Table_ExternalData_14[[#This Row],[Keterangan_Sukses]],VLOOKUP(Table_ExternalData_14[[#This Row],[ContractID]],Bantuan!$A:$C,3,0)) -> 0
A6: 1531 | B6: KUPANG | C6: 46142 | D6: 45962 | E6: 44592 | F6: 1531C20220100075 | G6: 1531220000015 | H6: SOFYAN | I6: JLN TURIN RT 012 RW 004 Kel.OETETE Kec. OEBOBO Kota KUPANG 85112 | J6: 85112 | L6: 85112 | M6: OETETE | N6: OEBOBO | O6: KUPANG | P6: 15310002 | Q6: Kefamenanu | T6: 00* | U6: 00* | V6: 08123******* | W6: MOBIL Baru | X6: SUZUKI | Y6: CARRY PU 1.5 | Z6: NEW CARRY PU FD | AA6: MHYHDC61TMJ260807 | AB6: K15BT1349453 | AC6: DH 8216 AP | AD6: 61376000 | AE6: 54467950 | AF6: 38360000 | AG6: 23016000 | AH6: 46077620 | AI6: 0 | AJ6: 3836000 | AK6: 180 | AL6: 6 | AM6: 45 | AN6: 60 | AO6: 06.151-180 | AP6: 06.151-180 | AQ6: 03.RO | AR6: 1531REM59 | AS6: 20230923758 | AT6: NOVENTIO CORNEL LUDJI | AU6: 1531ARC01 | AV6: 00000000000 | AW6: TIDAK ADA | AX6: RMC | AY6: 1531ARHEAD | AZ6: 20111111728 | BA6: DONALD E DALLY | BB6: RMH | BC6: 1531CH01 | BD6: 00000000000 | BE6: TIDAK ADA | BF6: Coll-Head | BG6: Collectible | BH6: 7 | BI6: 26852000 | BN6: 46173 | BO6: 1 | BP6: 46149 | BQ6: Coll Harian | BR6: 187 | BS6: 45962 | BT6: 61376000 | BU6: 0 | BV6: 1 | BW6: 0 | BX6: 0 | BY6: 0 | BZ6: 0 | CA6: 0 | CB6: 0 | CD6: 0 | CF6: 0 | CH6: 0 | CJ6: 0 | CL6: 0 | CM6: 46149 | CN6: 4W | CO6: 54467950 | CP6: 54467950 | CQ6: 1 | CT6: 0 | CU6: KUPANG - MBL | CV6: 11. Bali & Nusa Tenggara | CW6: 46149 | CX6: Last Month | CY6: =MONTH(Table_ExternalData_14[[#This Row],[RunningReportDate]]) -> 5 | CZ6: =181-Table_ExternalData_14[[#This Row],[DaysOD]] -> 1 | DA6: =IF(Table_ExternalData_14[[#This Row],[Status]]="PU-WC",0,Table_ExternalData_14[[#This Row],[Amount_CWO]]/1000000) -> 54.46795 | DB6: =IF(Table_ExternalData_14[[#This Row],[Status]]="PU-WC",0,IF(Table_ExternalData_14[[#This Row],[Keterangan_Sukses-new]]="RB",1,IF(Table_ExternalData_14[[#This Row],[Keterangan_Sukses-new]]="STAY",1,IF(Table_ExternalData_14[[#This Row],[Keterangan_Sukses-new]]="BTC",1,IF(ISERROR(FIND("SEBELUM",Table_ExternalData_14[[#This Row],[Keterangan_Sukses-new]],1)),0,1))))) -> 0 | DC6: =IF(Table_ExternalData_14[[#This Row],[Status]]="PU-WC",0,IF(Table_ExternalData_14[[#This Row],[Success CWO]]=1,Table_ExternalData_14[[#This Row],[CWO Amt]],0)) -> 0 | DD6: =IF(AND(Table_ExternalData_14[[#This Row],[Status]]="InsuranceClaim",Table_ExternalData_14[[#This Row],[TglTarik]]>0),0,IF(Table_ExternalData_14[[#This Row],[ContractID]]="1547220000067",0,IF(Table_ExternalData_14[[#This Row],[Status]]="PU-WC",0,IF(Table_ExternalData_14[[#This Row],[Tgl WO-in]]<= DAY(Table_ExternalData_14[[#This Row],[Period]]),Table_ExternalData_14[[#This Row],[Amount_WO]]/1000000,0)))) -> 54.46795 | DE6: =DAY(Table_ExternalData_14[[#This Row],[Tanggal_Sukses-new]]) -> 0 | DF6: =IF(Table_ExternalData_14[[#This Row],[Status]]="PU-WC",0,IF(SUM(Table_ExternalData_14[[#This Row],[Success CWO]:[WO-In-Amt]])=0,1,0)) -> 0 | DG6: =IF(AND(Table_ExternalData_14[[#This Row],[Status]]="InsuranceClaim",Table_ExternalData_14[[#This Row],[TglTarik]]>0),0,IF(Table_ExternalData_14[[#This Row],[Status]]="PU-WC",0,IF(Table_ExternalData_14[[#This Row],[Potensi WO]]=1,Table_ExternalData_14[[#This Row],[CWO Amt]],0))) -> 0 | DH6: =VLOOKUP(Table_ExternalData_14[[#This Row],[BranchID]],KC!$A:$K,5,0) -> 4W | DI6: =VLOOKUP(Table_ExternalData_14[[#This Row],[BranchID]],KC!$A:$K,8,0) -> 09. IBT | DJ6: =VLOOKUP(Table_ExternalData_14[[#This Row],[BranchID]],KC!$A:$K,9,0) -> KUPANG | DK6: =IF(Table_ExternalData_14[[#This Row],[Tanggal_Sukses]]=" ",Table_ExternalData_14[[#This Row],[Tanggal_Sukses]],VLOOKUP(Table_ExternalData_14[[#This Row],[ContractID]],Bantuan!$A:$C,2,0)) -> 0 | DL6: =IF(Table_ExternalData_14[[#This Row],[Keterangan_Sukses]]=" ",Table_ExternalData_14[[#This Row],[Keterangan_Sukses]],VLOOKUP(Table_ExternalData_14[[#This Row],[ContractID]],Bantuan!$A:$C,3,0)) -> 0
A7: 1531 | B7: KUPANG | C7: 46142 | D7: 45964 | E7: 44599 | F7: 1531C20220100144 | G7: 1531220000025 | H7: DANIEL BERE TEMU | I7: SUKABI WEDIK RT 001 RW 001 Kel.KAMANASA Kec. MALAKA TENGAH Kota MALAKA 85762 | J7: 85762 | L7: 85762 | M7: KAMANASA | N7: MALAKA TENGAH | O7: MALAKA | P7: 15310101 | Q7: Ende | T7: 00* | U7: 00* | V7: 08133******* | W7: MOBIL Baru | X7: SUZUKI | Y7: CARRY PU 1.5 | Z7: NEW CARRY PU FD | AA7: MHYHDC61TMJ260447 | AB7: K15BT1349202 | AC7: DH8834JB | AD7: 17520000 | AE7: 16911767 | AF7: 0 | AG7: 17520000 | AH7: 42298700 | AI7: 0 | AJ7: 4380000 | AK7: 178 | AL7: 4 | AM7: 45 | AN7: 48 | AO7: 06.151-180 | AP7: 06.151-180 | AQ7: 03.RO | AR7: 156396 | AS7: 20240423974 | AT7: ERIK YOHANES F NAISALI | AU7: 1531ARC01 | AV7: 00000000000 | AW7: TIDAK ADA | AX7: RMC | AY7: 1531ARHEAD | AZ7: 20111111728 | BA7: DONALD E DALLY | BB7: RMH | BC7: 1531CH01 | BD7: 00000000000 | BE7: TIDAK ADA | BF7: Coll-Head | BG7: Collectible | BH7: 4 | BI7: 17520000 | BN7: 46173 | BO7: 1 | BP7: 46149 | BQ7: Coll Harian | BR7: 185 | BS7: 45964 | BT7: 17520000 | BU7: 0 | BV7: 1 | BW7: 0 | BX7: 0 | BY7: 0 | BZ7: 0 | CA7: 0 | CB7: 0 | CD7: 0 | CF7: 0 | CH7: 0 | CJ7: 0 | CL7: 0 | CM7: 46149 | CN7: 4W | CO7: 16911767 | CP7: 16911767 | CQ7: 3 | CT7: 0 | CU7: KUPANG - MBL | CV7: 11. Bali & Nusa Tenggara | CW7: 46149 | CX7: Last Month | CY7: =MONTH(Table_ExternalData_14[[#This Row],[RunningReportDate]]) -> 5 | CZ7: =181-Table_ExternalData_14[[#This Row],[DaysOD]] -> 3 | DA7: =IF(Table_ExternalData_14[[#This Row],[Status]]="PU-WC",0,Table_ExternalData_14[[#This Row],[Amount_CWO]]/1000000) -> 16.911767 | DB7: =IF(Table_ExternalData_14[[#This Row],[Status]]="PU-WC",0,IF(Table_ExternalData_14[[#This Row],[Keterangan_Sukses-new]]="RB",1,IF(Table_ExternalData_14[[#This Row],[Keterangan_Sukses-new]]="STAY",1,IF(Table_ExternalData_14[[#This Row],[Keterangan_Sukses-new]]="BTC",1,IF(ISERROR(FIND("SEBELUM",Table_ExternalData_14[[#This Row],[Keterangan_Sukses-new]],1)),0,1))))) -> 0 | DC7: =IF(Table_ExternalData_14[[#This Row],[Status]]="PU-WC",0,IF(Table_ExternalData_14[[#This Row],[Success CWO]]=1,Table_ExternalData_14[[#This Row],[CWO Amt]],0)) -> 0 | DD7: =IF(AND(Table_ExternalData_14[[#This Row],[Status]]="InsuranceClaim",Table_ExternalData_14[[#This Row],[TglTarik]]>0),0,IF(Table_ExternalData_14[[#This Row],[ContractID]]="1547220000067",0,IF(Table_ExternalData_14[[#This Row],[Status]]="PU-WC",0,IF(Table_ExternalData_14[[#This Row],[Tgl WO-in]]<= DAY(Table_ExternalData_14[[#This Row],[Period]]),Table_ExternalData_14[[#This Row],[Amount_WO]]/1000000,0)))) -> 16.911767 | DE7: =DAY(Table_ExternalData_14[[#This Row],[Tanggal_Sukses-new]]) -> 0 | DF7: =IF(Table_ExternalData_14[[#This Row],[Status]]="PU-WC",0,IF(SUM(Table_ExternalData_14[[#This Row],[Success CWO]:[WO-In-Amt]])=0,1,0)) -> 0 | DG7: =IF(AND(Table_ExternalData_14[[#This Row],[Status]]="InsuranceClaim",Table_ExternalData_14[[#This Row],[TglTarik]]>0),0,IF(Table_ExternalData_14[[#This Row],[Status]]="PU-WC",0,IF(Table_ExternalData_14[[#This Row],[Potensi WO]]=1,Table_ExternalData_14[[#This Row],[CWO Amt]],0))) -> 0 | DH7: =VLOOKUP(Table_ExternalData_14[[#This Row],[BranchID]],KC!$A:$K,5,0) -> 4W | DI7: =VLOOKUP(Table_ExternalData_14[[#This Row],[BranchID]],KC!$A:$K,8,0) -> 09. IBT | DJ7: =VLOOKUP(Table_ExternalData_14[[#This Row],[BranchID]],KC!$A:$K,9,0) -> KUPANG | DK7: =IF(Table_ExternalData_14[[#This Row],[Tanggal_Sukses]]=" ",Table_ExternalData_14[[#This Row],[Tanggal_Sukses]],VLOOKUP(Table_ExternalData_14[[#This Row],[ContractID]],Bantuan!$A:$C,2,0)) -> 0 | DL7: =IF(Table_ExternalData_14[[#This Row],[Keterangan_Sukses]]=" ",Table_ExternalData_14[[#This Row],[Keterangan_Sukses]],VLOOKUP(Table_ExternalData_14[[#This Row],[ContractID]],Bantuan!$A:$C,3,0)) -> 0
A8: 1531 | B8: KUPANG | C8: 46142 | D8: 45968 | E8: 45176 | F8: 1531C20230700153 | G8: 1531230000230 | H8: KRISTIAN DAVID | I8: PARITI RT 017 RW 009 Kel.PARITI Kec. SULAMU Kota KUPANG 85368 | J8: 85368 | L8: 85368 | M8: PARITI | N8: SULAMU | O8: KUPANG | P8: 15310000 | Q8: Kupang | V8: 08123******* | W8: MOBIL Baru | X8: SUZUKI | Y8: CARRY PU 1.5 | Z8: NEW CARRY PU FD | AA8: MHYHDC61TPJ215633 | AB8: K15BT1503516 | AC8: DH8853BH | AD8: 138448000 | AE8: 1.1077377e+08 | AF8: 114016000 | AG8: 24432000 | AH8: 33286520 | AI8: 1000 | AJ8: 4072000 | AK8: 174 | AL8: 6 | AM8: 27 | AN8: 60 | AO8: 06.151-180 | AP8: 06.151-180 | AQ8: 03.RO | AR8: 1531REM59 | AS8: 20230923758 | AT8: NOVENTIO CORNEL LUDJI | AU8: 1531ARC01 | AV8: 00000000000 | AW8: TIDAK ADA | AX8: RMC | AY8: 1531ARHEAD | AZ8: 20111111728 | BA8: DONALD E DALLY | BB8: RMH | BC8: 1531CH01 | BD8: 00000000000 | BE8: TIDAK ADA | BF8: Coll-Head | BG8: Collectible | BH8: 7 | BI8: 28504000 | BN8: 46173 | BO8: 1 | BP8: 46149 | BQ8: Coll Harian | BR8: 151 | BS8: 45998 | BT8: 134376000 | BU8: 4072000 | BV8: 0 | BW8: 0 | BX8: 0 | BY8: 1 | BZ8: 1 | CA8: 4072000 | CB8: 4072000 | CD8: 0 | CF8: 0 | CH8: 0 | CJ8: 0 | CL8: 0 | CM8: 46149 | CN8: 4W | CO8: 1.1077277e+08 | CP8: 0 | CQ8: 0 | CR8: 46144 | CS8: RB | CT8: 1.1077277e+08 | CU8: KUPANG - MBL | CV8: 11. Bali & Nusa Tenggara | CW8: 46149 | CX8: Last Month | CY8: =MONTH(Table_ExternalData_14[[#This Row],[RunningReportDate]]) -> 5 | CZ8: =181-Table_ExternalData_14[[#This Row],[DaysOD]] -> 7 | DA8: =IF(Table_ExternalData_14[[#This Row],[Status]]="PU-WC",0,Table_ExternalData_14[[#This Row],[Amount_CWO]]/1000000) -> 110.77277 | DB8: =IF(Table_ExternalData_14[[#This Row],[Status]]="PU-WC",0,IF(Table_ExternalData_14[[#This Row],[Keterangan_Sukses-new]]="RB",1,IF(Table_ExternalData_14[[#This Row],[Keterangan_Sukses-new]]="STAY",1,IF(Table_ExternalData_14[[#This Row],[Keterangan_Sukses-new]]="BTC",1,IF(ISERROR(FIND("SEBELUM",Table_ExternalData_14[[#This Row],[Keterangan_Sukses-new]],1)),0,1))))) -> 1 | DC8: =IF(Table_ExternalData_14[[#This Row],[Status]]="PU-WC",0,IF(Table_ExternalData_14[[#This Row],[Success CWO]]=1,Table_ExternalData_14[[#This Row],[CWO Amt]],0)) -> 110.77277 | DD8: =IF(AND(Table_ExternalData_14[[#This Row],[Status]]="InsuranceClaim",Table_ExternalData_14[[#This Row],[TglTarik]]>0),0,IF(Table_ExternalData_14[[#This Row],[ContractID]]="1547220000067",0,IF(Table_ExternalData_14[[#This Row],[Status]]="PU-WC",0,IF(Table_ExternalData_14[[#This Row],[Tgl WO-in]]<= DAY(Table_ExternalData_14[[#This Row],[Period]]),Table_ExternalData_14[[#This Row],[Amount_WO]]/1000000,0)))) -> 0 | DE8: =DAY(Table_ExternalData_14[[#This Row],[Tanggal_Sukses-new]]) -> 2 | DF8: =IF(Table_ExternalData_14[[#This Row],[Status]]="PU-WC",0,IF(SUM(Table_ExternalData_14[[#This Row],[Success CWO]:[WO-In-Amt]])=0,1,0)) -> 0 | DG8: =IF(AND(Table_ExternalData_14[[#This Row],[Status]]="InsuranceClaim",Table_ExternalData_14[[#This Row],[TglTarik]]>0),0,IF(Table_ExternalData_14[[#This Row],[Status]]="PU-WC",0,IF(Table_ExternalData_14[[#This Row],[Potensi WO]]=1,Table_ExternalData_14[[#This Row],[CWO Amt]],0))) -> 0 | DH8: =VLOOKUP(Table_ExternalData_14[[#This Row],[BranchID]],KC!$A:$K,5,0) -> 4W | DI8: =VLOOKUP(Table_ExternalData_14[[#This Row],[BranchID]],KC!$A:$K,8,0) -> 09. IBT | DJ8: =VLOOKUP(Table_ExternalData_14[[#This Row],[BranchID]],KC!$A:$K,9,0) -> KUPANG | DK8: =IF(Table_ExternalData_14[[#This Row],[Tanggal_Sukses]]=" ",Table_ExternalData_14[[#This Row],[Tanggal_Sukses]],VLOOKUP(Table_ExternalData_14[[#This Row],[ContractID]],Bantuan!$A:$C,2,0)) -> 46144 | DL8: =IF(Table_ExternalData_14[[#This Row],[Keterangan_Sukses]]=" ",Table_ExternalData_14[[#This Row],[Keterangan_Sukses]],VLOOKUP(Table_ExternalData_14[[#This Row],[ContractID]],Bantuan!$A:$C,3,0)) -> RB
A9: 1531 | B9: KUPANG | C9: 46142 | D9: 45966 | E9: 45175 | F9: 1531C20230800026 | G9: 1531230000233 | H9: VICTOR YONARI NDUN | I9: JL CENDAWAN RT 016 RW 004 Kel.LASIANA Kec. KELAPA LIMA Kota KUPANG 85228 | J9: 85228 | L9: 85228 | M9: LASIANA | N9: KELAPA LIMA | O9: KUPANG | P9: 15310000 | Q9: Kupang | V9: 08133******* | W9: MOBIL Baru | X9: SUZUKI | Y9: CARRY PU 1.5 | Z9: NEW CARRY PU FD | AA9: MHYHDC61TPJ215365 | AB9: K15BT1503097 | AC9: DH8514AQ | AD9: 162880000 | AE9: 1.2923575e+08 | AF9: 138448000 | AG9: 24432000 | AH9: 44128500 | AI9: 50000 | AJ9: 4072000 | AK9: 176 | AL9: 6 | AM9: 26 | AN9: 65 | AO9: 06.151-180 | AP9: 06.151-180 | AQ9: 03.RO | AR9: 1531REM59 | AS9: 20230923758 | AT9: NOVENTIO CORNEL LUDJI | AU9: 1531ARC01 | AV9: 00000000000 | AW9: TIDAK ADA | AX9: RMC | AY9: 1531ARHEAD | AZ9: 20111111728 | BA9: DONALD E DALLY | BB9: RMH | BC9: 1531CH01 | BD9: 00000000000 | BE9: TIDAK ADA | BF9: Coll-Head | BG9: Collectible | BH9: 7 | BI9: 28504000 | BN9: 46173 | BO9: 1 | BP9: 46149 | BQ9: Coll Harian | BR9: 153 | BS9: 45996 | BT9: 158808000 | BU9: 4072000 | BV9: 0 | BW9: 0 | BX9: 0 | BY9: 1 | BZ9: 1 | CA9: 4072000 | CB9: 4072000 | CD9: 0 | CF9: 0 | CH9: 0 | CJ9: 0 | CL9: 0 | CM9: 46149 | CN9: 4W | CO9: 1.2918575e+08 | CP9: 0 | CQ9: 0 | CR9: 46146 | CS9: RB | CT9: 1.2918575e+08 | CU9: KUPANG - MBL | CV9: 11. Bali & Nusa Tenggara | CW9: 46149 | CX9: Last Month | CY9: =MONTH(Table_ExternalData_14[[#This Row],[RunningReportDate]]) -> 5 | CZ9: =181-Table_ExternalData_14[[#This Row],[DaysOD]] -> 5 | DA9: =IF(Table_ExternalData_14[[#This Row],[Status]]="PU-WC",0,Table_ExternalData_14[[#This Row],[Amount_CWO]]/1000000) -> 129.18575 | DB9: =IF(Table_ExternalData_14[[#This Row],[Status]]="PU-WC",0,IF(Table_ExternalData_14[[#This Row],[Keterangan_Sukses-new]]="RB",1,IF(Table_ExternalData_14[[#This Row],[Keterangan_Sukses-new]]="STAY",1,IF(Table_ExternalData_14[[#This Row],[Keterangan_Sukses-new]]="BTC",1,IF(ISERROR(FIND("SEBELUM",Table_ExternalData_14[[#This Row],[Keterangan_Sukses-new]],1)),0,1))))) -> 1 | DC9: =IF(Table_ExternalData_14[[#This Row],[Status]]="PU-WC",0,IF(Table_ExternalData_14[[#This Row],[Success CWO]]=1,Table_ExternalData_14[[#This Row],[CWO Amt]],0)) -> 129.18575 | DD9: =IF(AND(Table_ExternalData_14[[#This Row],[Status]]="InsuranceClaim",Table_ExternalData_14[[#This Row],[TglTarik]]>0),0,IF(Table_ExternalData_14[[#This Row],[ContractID]]="1547220000067",0,IF(Table_ExternalData_14[[#This Row],[Status]]="PU-WC",0,IF(Table_ExternalData_14[[#This Row],[Tgl WO-in]]<= DAY(Table_ExternalData_14[[#This Row],[Period]]),Table_ExternalData_14[[#This Row],[Amount_WO]]/1000000,0)))) -> 0 | DE9: =DAY(Table_ExternalData_14[[#This Row],[Tanggal_Sukses-new]]) -> 4 | DF9: =IF(Table_ExternalData_14[[#This Row],[Status]]="PU-WC",0,IF(SUM(Table_ExternalData_14[[#This Row],[Success CWO]:[WO-In-Amt]])=0,1,0)) -> 0 | DG9: =IF(AND(Table_ExternalData_14[[#This Row],[Status]]="InsuranceClaim",Table_ExternalData_14[[#This Row],[TglTarik]]>0),0,IF(Table_ExternalData_14[[#This Row],[Status]]="PU-WC",0,IF(Table_ExternalData_14[[#This Row],[Potensi WO]]=1,Table_ExternalData_14[[#This Row],[CWO Amt]],0))) -> 0 | DH9: =VLOOKUP(Table_ExternalData_14[[#This Row],[BranchID]],KC!$A:$K,5,0) -> 4W | DI9: =VLOOKUP(Table_ExternalData_14[[#This Row],[BranchID]],KC!$A:$K,8,0) -> 09. IBT | DJ9: =VLOOKUP(Table_ExternalData_14[[#This Row],[BranchID]],KC!$A:$K,9,0) -> KUPANG | DK9: =IF(Table_ExternalData_14[[#This Row],[Tanggal_Sukses]]=" ",Table_ExternalData_14[[#This Row],[Tanggal_Sukses]],VLOOKUP(Table_ExternalData_14[[#This Row],[ContractID]],Bantuan!$A:$C,2,0)) -> 46146 | DL9: =IF(Table_ExternalData_14[[#This Row],[Keterangan_Sukses]]=" ",Table_ExternalData_14[[#This Row],[Keterangan_Sukses]],VLOOKUP(Table_ExternalData_14[[#This Row],[ContractID]],Bantuan!$A:$C,3,0)) -> RB
A10: 1531 | B10: KUPANG | C10: 46142 | D10: 45966 | E10: 45594 | F10: 1531C20241000090 | G10: 1531240000179 | H10: SAMUEL TEKLIU | I10: BESNAEN RT 039 RW 005 Kel.MAUBELI Kec. KOTA KEFAMENANU Kota TIMOR TENGAH UTARA 85617 | J10: 85617 | L10: 85617 | M10: MAUBELI | N10: KOTA KEFAMENANU | O10: TIMOR TENGAH UTARA | P10: 15310002 | Q10: Kupang | V10: 08234******* | W10: MOBIL Baru | X10: SUZUKI | Y10: CARRY PU 1.5 | Z10: NEW CARRY PU FD | AA10: MHYHDC61TRJ215558 | AB10: K15BT1608076 | AC10: DH 8529 DL | AD10: 203315000 | AE10: 1.4648393e+08 | AF10: 170345000 | AG10: 32970000 | AH10: 21375550 | AI10: 0 | AJ10: 5495000 | AK10: 176 | AL10: 6 | AM10: 12 | AN10: 48 | AO10: 06.151-180 | AP10: 06.151-180 | AQ10: 03.RO | AR10: 156396 | AS10: 20240423974 | AT10: ERIK YOHANES F NAISALI | AU10: 1531ARC01 | AV10: 00000000000 | AW10: TIDAK ADA | AX10: RMC | AY10: 1531ARHEAD | AZ10: 20111111728 | BA10: DONALD E DALLY | BB10: RMH | BC10: 1531CH01 | BD10: 00000000000 | BE10: TIDAK ADA | BF10: Coll-Head | BG10: Collectible | BH10: 7 | BI10: 38465000 | BN10: 46173 | BO10: 1 | BP10: 46149 | BQ10: Coll Harian | BR10: 183 | BS10: 45966 | BT10: 203315000 | BU10: 0 | BV10: 1 | BW10: 0 | BX10: 0 | BY10: 0 | BZ10: 0 | CA10: 0 | CB10: 0 | CD10: 0 | CF10: 0 | CH10: 0 | CJ10: 0 | CL10: 0 | CM10: 46149 | CN10: 4W | CO10: 1.4648393e+08 | CP10: 1.4648393e+08 | CQ10: 5 | CT10: 0 | CU10: KUPANG - MBL | CV10: 11. Bali & Nusa Tenggara | CW10: 46149 | CX10: Last Month | CY10: =MONTH(Table_ExternalData_14[[#This Row],[RunningReportDate]]) -> 5 | CZ10: =181-Table_ExternalData_14[[#This Row],[DaysOD]] -> 5 | DA10: =IF(Table_ExternalData_14[[#This Row],[Status]]="PU-WC",0,Table_ExternalData_14[[#This Row],[Amount_CWO]]/1000000) -> 146.48393 | DB10: =IF(Table_ExternalData_14[[#This Row],[Status]]="PU-WC",0,IF(Table_ExternalData_14[[#This Row],[Keterangan_Sukses-new]]="RB",1,IF(Table_ExternalData_14[[#This Row],[Keterangan_Sukses-new]]="STAY",1,IF(Table_ExternalData_14[[#This Row],[Keterangan_Sukses-new]]="BTC",1,IF(ISERROR(FIND("SEBELUM",Table_ExternalData_14[[#This Row],[Keterangan_Sukses-new]],1)),0,1))))) -> 0 | DC10: =IF(Table_ExternalData_14[[#This Row],[Status]]="PU-WC",0,IF(Table_ExternalData_14[[#This Row],[Success CWO]]=1,Table_ExternalData_14[[#This Row],[CWO Amt]],0)) -> 0 | DD10: =IF(AND(Table_ExternalData_14[[#This Row],[Status]]="InsuranceClaim",Table_ExternalData_14[[#This Row],[TglTarik]]>0),0,IF(Table_ExternalData_14[[#This Row],[ContractID]]="1547220000067",0,IF(Table_ExternalData_14[[#This Row],[Status]]="PU-WC",0,IF(Table_ExternalData_14[[#This Row],[Tgl WO-in]]<= DAY(Table_ExternalData_14[[#This Row],[Period]]),Table_ExternalData_14[[#This Row],[Amount_WO]]/1000000,0)))) -> 146.48393 | DE10: =DAY(Table_ExternalData_14[[#This Row],[Tanggal_Sukses-new]]) -> 0 | DF10: =IF(Table_ExternalData_14[[#This Row],[Status]]="PU-WC",0,IF(SUM(Table_ExternalData_14[[#This Row],[Success CWO]:[WO-In-Amt]])=0,1,0)) -> 0 | DG10: =IF(AND(Table_ExternalData_14[[#This Row],[Status]]="InsuranceClaim",Table_ExternalData_14[[#This Row],[TglTarik]]>0),0,IF(Table_ExternalData_14[[#This Row],[Status]]="PU-WC",0,IF(Table_ExternalData_14[[#This Row],[Potensi WO]]=1,Table_ExternalData_14[[#This Row],[CWO Amt]],0))) -> 0 | DH10: =VLOOKUP(Table_ExternalData_14[[#This Row],[BranchID]],KC!$A:$K,5,0) -> 4W | DI10: =VLOOKUP(Table_ExternalData_14[[#This Row],[BranchID]],KC!$A:$K,8,0) -> 09. IBT | DJ10: =VLOOKUP(Table_ExternalData_14[[#This Row],[BranchID]],KC!$A:$K,9,0) -> KUPANG | DK10: =IF(Table_ExternalData_14[[#This Row],[Tanggal_Sukses]]=" ",Table_ExternalData_14[[#This Row],[Tanggal_Sukses]],VLOOKUP(Table_ExternalData_14[[#This Row],[ContractID]],Bantuan!$A:$C,2,0)) -> 0 | DL10: =IF(Table_ExternalData_14[[#This Row],[Keterangan_Sukses]]=" ",Table_ExternalData_14[[#This Row],[Keterangan_Sukses]],VLOOKUP(Table_ExternalData_14[[#This Row],[ContractID]],Bantuan!$A:$C,3,0)) -> 0
A11: 1532 | B11: PALEMBANG | C11: 46142 | D11: 45983 | E11: 44511 | F11: 1532C20211100001 | G11: 1532210000049 | H11: EMI WATI | I11: DESA PAGAR BANYU RT 0 RW 0 Kel.PAGAR BANYU Kec. ARGA MAKMUR Kota BENGKULU UTARA 38611 | J11: 38611 | L11: 38611 | M11: PAGAR BANYU | N11: ARGA MAKMUR | O11: BENGKULU UTARA | P11: 15320000 | Q11: Bengkulu | T11: 8941**** | U11: 8941**** | V11: 08217******* | W11: MOBIL Baru | X11: SUZUKI | Y11: CARRY PU 1.5 | Z11: NEW CARRY PU FD | AA11: MHYHDC61TMJ246054 | AB11: K15BT1316037 | AC11: BD 9004 DF | AD11: 26509000 | AE11: 25092283 | AF11: 3787000 | AG11: 22722000 | AH11: 36277776 | AI11: 390 | AJ11: 3787000 | AK11: 159 | AL11: 6 | AM11: 48 | AN11: 54 | AO11: 06.151-180 | AP11: 06.151-180 | AQ11: 03.RO | BF11: Coll-Head | BG11: Collectible | BH11: 7 | BI11: 26509000 | BN11: 46173 | BO11: 1 | BP11: 46149 | BQ11: Coll Harian | BR11: 136 | BS11: 46013 | BT11: 22722000 | BU11: 3787000 | BV11: 0 | BW11: 0 | BX11: 0 | BY11: 1 | BZ11: 1 | CA11: 3787000 | CB11: 3787000 | CD11: 0 | CF11: 0 | CH11: 0 | CJ11: 0 | CL11: 0 | CM11: 46149 | CN11: 4W | CO11: 25091893 | CP11: 0 | CQ11: 0 | CR11: 46149 | CS11: RB | CT11: 25091893 | CU11: PALEMBANG 3 - MBL | CV11: 06. Sumatera Selatan | CW11: 46149 | CX11: Last Month | CY11: =MONTH(Table_ExternalData_14[[#This Row],[RunningReportDate]]) -> 5 | CZ11: =181-Table_ExternalData_14[[#This Row],[DaysOD]] -> 22 | DA11: =IF(Table_ExternalData_14[[#This Row],[Status]]="PU-WC",0,Table_ExternalData_14[[#This Row],[Amount_CWO]]/1000000) -> 25.091893 | DB11: =IF(Table_ExternalData_14[[#This Row],[Status]]="PU-WC",0,IF(Table_ExternalData_14[[#This Row],[Keterangan_Sukses-new]]="RB",1,IF(Table_ExternalData_14[[#This Row],[Keterangan_Sukses-new]]="STAY",1,IF(Table_ExternalData_14[[#This Row],[Keterangan_Sukses-new]]="BTC",1,IF(ISERROR(FIND("SEBELUM",Table_ExternalData_14[[#This Row],[Keterangan_Sukses-new]],1)),0,1))))) -> 1 | DC11: =IF(Table_ExternalData_14[[#This Row],[Status]]="PU-WC",0,IF(Table_ExternalData_14[[#This Row],[Success CWO]]=1,Table_ExternalData_14[[#This Row],[CWO Amt]],0)) -> 25.091893 | DD11: =IF(AND(Table_ExternalData_14[[#This Row],[Status]]="InsuranceClaim",Table_ExternalData_14[[#This Row],[TglTarik]]>0),0,IF(Table_ExternalData_14[[#This Row],[ContractID]]="1547220000067",0,IF(Table_ExternalData_14[[#This Row],[Status]]="PU-WC",0,IF(Table_ExternalData_14[[#This Row],[Tgl WO-in]]<= DAY(Table_ExternalData_14[[#This Row],[Period]]),Table_ExternalData_14[[#This Row],[Amount_WO]]/1000000,0)))) -> 0 | DE11: =DAY(Table_ExternalData_14[[#This Row],[Tanggal_Sukses-new]]) -> 7 | DF11: =IF(Table_ExternalData_14[[#This Row],[Status]]="PU-WC",0,IF(SUM(Table_ExternalData_14[[#This Row],[Success CWO]:[WO-In-Amt]])=0,1,0)) -> 0 | DG11: =IF(AND(Table_ExternalData_14[[#This Row],[Status]]="InsuranceClaim",Table_ExternalData_14[[#This Row],[TglTarik]]>0),0,IF(Table_ExternalData_14[[#This Row],[Status]]="PU-WC",0,IF(Table_ExternalData_14[[#This Row],[Potensi WO]]=1,Table_ExternalData_14[[#This Row],[CWO Amt]],0))) -> 0 | DH11: =VLOOKUP(Table_ExternalData_14[[#This Row],[BranchID]],KC!$A:$K,5,0) -> 4W | DI11: =VLOOKUP(Table_ExternalData_14[[#This Row],[BranchID]],KC!$A:$K,8,0) -> 07. Sumbagsel | DJ11: =VLOOKUP(Table_ExternalData_14[[#This Row],[BranchID]],KC!$A:$K,9,0) -> PALEMBANG | DK11: =IF(Table_ExternalData_14[[#This Row],[Tanggal_Sukses]]=" ",Table_ExternalData_14[[#This Row],[Tanggal_Sukses]],VLOOKUP(Table_ExternalData_14[[#This Row],[ContractID]],Bantuan!$A:$C,2,0)) -> 46149 | DL11: =IF(Table_ExternalData_14[[#This Row],[Keterangan_Sukses]]=" ",Table_ExternalData_14[[#This Row],[Keterangan_Sukses]],VLOOKUP(Table_ExternalData_14[[#This Row],[ContractID]],Bantuan!$A:$C,3,0)) -> RB
A12: 1532 | B12: PALEMBANG | C12: 46142 | D12: 45968 | E12: 44537 | F12: 1532C20211200004 | G12: 1532210000056 | H12: MEDI RIANSYAH PUTRA | I12: JL SAPTA MARGA RT 05 RW 01 Kel.TALANG RIMBO LAMA Kec. CURUP TENGAH Kota REJANG LEBONG 39114 | J12: 39114 | L12: 39114 | M12: TALANG RIMBO LAMA | N12: CURUP TENGAH | O12: REJANG LEBONG | P12: 15320000 | Q12: Bengkulu | T12: 7379**** | U12: 7379**** | V12: 08127******* | W12: MOBIL Baru | X12: SUZUKI | Y12: CARRY PU 1.5 | Z12: NEW CARRY PU FD | AA12: MHYHDC61TMJ253507 | AB12: K15BT1331497 | AC12: BD 9164 KC | AD12: 3855000 | AE12: 3801144.1 | AF12: 0 | AG12: 3855000 | AH12: 40477250 | AI12: 0 | AJ12: 3855000 | AK12: 174 | AL12: 1 | AM12: 48 | AN12: 48 | AO12: 06.151-180 | AP12: 06.151-180 | AQ12: 03.RO | BF12: Coll-Head | BG12: Collectible | BH12: 1 | BI12: 3855000 | BN12: 46173 | BO12: 1 | BP12: 46149 | BQ12: Non Coll Harian | BT12: 0 | BU12: 3855000 | BV12: 0 | BW12: 1 | BX12: 1 | BY12: 1 | BZ12: 1 | CA12: 3855000 | CB12: 3855000 | CD12: 0 | CF12: 0 | CH12: 0 | CJ12: 0 | CL12: 0 | CM12: 46149 | CN12: 4W | CO12: 3801144.1 | CP12: 0 | CQ12: 0 | CR12: 46149 | CS12: LUNAS SEBELUM WO | CT12: 3801144.1 | CU12: PALEMBANG 3 - MBL | CV12: 06. Sumatera Selatan | CW12: 46149 | CX12: Last Month | CY12: =MONTH(Table_ExternalData_14[[#This Row],[RunningReportDate]]) -> 5 | CZ12: =181-Table_ExternalData_14[[#This Row],[DaysOD]] -> 7 | DA12: =IF(Table_ExternalData_14[[#This Row],[Status]]="PU-WC",0,Table_ExternalData_14[[#This Row],[Amount_CWO]]/1000000) -> 3.8011441 | DB12: =IF(Table_ExternalData_14[[#This Row],[Status]]="PU-WC",0,IF(Table_ExternalData_14[[#This Row],[Keterangan_Sukses-new]]="RB",1,IF(Table_ExternalData_14[[#This Row],[Keterangan_Sukses-new]]="STAY",1,IF(Table_ExternalData_14[[#This Row],[Keterangan_Sukses-new]]="BTC",1,IF(ISERROR(FIND("SEBELUM",Table_ExternalData_14[[#This Row],[Keterangan_Sukses-new]],1)),0,1))))) -> 1 | DC12: =IF(Table_ExternalData_14[[#This Row],[Status]]="PU-WC",0,IF(Table_ExternalData_14[[#This Row],[Success CWO]]=1,Table_ExternalData_14[[#This Row],[CWO Amt]],0)) -> 3.8011441 | DD12: =IF(AND(Table_ExternalData_14[[#This Row],[Status]]="InsuranceClaim",Table_ExternalData_14[[#This Row],[TglTarik]]>0),0,IF(Table_ExternalData_14[[#This Row],[ContractID]]="1547220000067",0,IF(Table_ExternalData_14[[#This Row],[Status]]="PU-WC",0,IF(Table_ExternalData_14[[#This Row],[Tgl WO-in]]<= DAY(Table_ExternalData_14[[#This Row],[Period]]),Table_ExternalData_14[[#This Row],[Amount_WO]]/1000000,0)))) -> 0 | DE12: =DAY(Table_ExternalData_14[[#This Row],[Tanggal_Sukses-new]]) -> 7 | DF12: =IF(Table_ExternalData_14[[#This Row],[Status]]="PU-WC",0,IF(SUM(Table_ExternalData_14[[#This Row],[Success CWO]:[WO-In-Amt]])=0,1,0)) -> 0 | DG12: =IF(AND(Table_ExternalData_14[[#This Row],[Status]]="InsuranceClaim",Table_ExternalData_14[[#This Row],[TglTarik]]>0),0,IF(Table_ExternalData_14[[#This Row],[Status]]="PU-WC",0,IF(Table_ExternalData_14[[#This Row],[Potensi WO]]=1,Table_ExternalData_14[[#This Row],[CWO Amt]],0))) -> 0 | DH12: =VLOOKUP(Table_ExternalData_14[[#This Row],[BranchID]],KC!$A:$K,5,0) -> 4W | DI12: =VLOOKUP(Table_ExternalData_14[[#This Row],[BranchID]],KC!$A:$K,8,0) -> 07. Sumbagsel | DJ12: =VLOOKUP(Table_ExternalData_14[[#This Row],[BranchID]],KC!$A:$K,9,0) -> PALEMBANG | DK12: =IF(Table_ExternalData_14[[#This Row],[Tanggal_Sukses]]=" ",Table_ExternalData_14[[#This Row],[Tanggal_Sukses]],VLOOKUP(Table_ExternalData_14[[#This Row],[ContractID]],Bantuan!$A:$C,2,0)) -> 46149 | DL12: =IF(Table_ExternalData_14[[#This Row],[Keterangan_Sukses]]=" ",Table_ExternalData_14[[#This Row],[Keterangan_Sukses]],VLOOKUP(Table_ExternalData_14[[#This Row],[ContractID]],Bantuan!$A:$C,3,0)) -> LUNAS SEBELUM WO
A13: 1532 | B13: PALEMBANG | C13: 46142 | D13: 45987 | E13: 44587 | F13: 1532C20220100013 | G13: 1532220000003 | H13: SADAR RAMLAN SINAGA | I13: PULAI PAYUNG RT 000 RW 000 Kel.PULAI PAYUNG Kec. IPUH Kota KABUPATEN MUKO MUKO 38364 | J13: 38364 | L13: 38364 | M13: PULAI PAYUNG | N13: IPUH | O13: KABUPATEN MUKO MUKO | P13: 15320000 | Q13: Bengkulu | T13: 1705**** | U13: 1705**** | V13: 08221******* | W13: MOBIL Baru | X13: SUZUKI | Y13: CARRY PU 1.5 | Z13: NEW CARRY PU FD AC PS | AA13: MHYHDC61TMJ258830 | AB13: K15BT1346278 | AC13: BD 9384 ND | AD13: 11550000 | AE13: 11244905 | AF13: 0 | AG13: 11550000 | AH13: 36879908 | AI13: 5500 | AJ13: 3850000 | AK13: 155 | AL13: 3 | AM13: 46 | AN13: 48 | AO13: 06.151-180 | AP13: 06.151-180 | AQ13: 03.RO | BF13: Coll-Head | BG13: Collectible | BH13: 3 | BI13: 11550000 | BN13: 46173 | BO13: 1 | BP13: 46149 | BQ13: Coll Harian | BR13: 162 | BS13: 45987 | BT13: 11550000 | BU13: 0 | BV13: 1 | BW13: 0 | BX13: 0 | BY13: 0 | BZ13: 0 | CA13: 0 | CB13: 0 | CD13: 0 | CF13: 0 | CH13: 0 | CJ13: 0 | CL13: 0 | CM13: 46149 | CN13: 4W | CO13: 11239405 | CP13: 11239405 | CQ13: 26 | CT13: 0 | CU13: PALEMBANG 3 - MBL | CV13: 06. Sumatera Selatan | CW13: 46149 | CX13: Last Month | CY13: =MONTH(Table_ExternalData_14[[#This Row],[RunningReportDate]]) -> 5 | CZ13: =181-Table_ExternalData_14[[#This Row],[DaysOD]] -> 26 | DA13: =IF(Table_ExternalData_14[[#This Row],[Status]]="PU-WC",0,Table_ExternalData_14[[#This Row],[Amount_CWO]]/1000000) -> 11.239405 | DB13: =IF(Table_ExternalData_14[[#This Row],[Status]]="PU-WC",0,IF(Table_ExternalData_14[[#This Row],[Keterangan_Sukses-new]]="RB",1,IF(Table_ExternalData_14[[#This Row],[Keterangan_Sukses-new]]="STAY",1,IF(Table_ExternalData_14[[#This Row],[Keterangan_Sukses-new]]="BTC",1,IF(ISERROR(FIND("SEBELUM",Table_ExternalData_14[[#This Row],[Keterangan_Sukses-new]],1)),0,1))))) -> 0 | DC13: =IF(Table_ExternalData_14[[#This Row],[Status]]="PU-WC",0,IF(Table_ExternalData_14[[#This Row],[Success CWO]]=1,Table_ExternalData_14[[#This Row],[CWO Amt]],0)) -> 0 | DD13: =IF(AND(Table_ExternalData_14[[#This Row],[Status]]="InsuranceClaim",Table_ExternalData_14[[#This Row],[TglTarik]]>0),0,IF(Table_ExternalData_14[[#This Row],[ContractID]]="1547220000067",0,IF(Table_ExternalData_14[[#This Row],[Status]]="PU-WC",0,IF(Table_ExternalData_14[[#This Row],[Tgl WO-in]]<= DAY(Table_ExternalData_14[[#This Row],[Period]]),Table_ExternalData_14[[#This Row],[Amount_WO]]/1000000,0)))) -> 0 | DE13: =DAY(Table_ExternalData_14[[#This Row],[Tanggal_Sukses-new]]) -> 0 | DF13: =IF(Table_ExternalData_14[[#This Row],[Status]]="PU-WC",0,IF(SUM(Table_ExternalData_14[[#This Row],[Success CWO]:[WO-In-Amt]])=0,1,0)) -> 1 | DG13: =IF(AND(Table_ExternalData_14[[#This Row],[Status]]="InsuranceClaim",Table_ExternalData_14[[#This Row],[TglTarik]]>0),0,IF(Table_ExternalData_14[[#This Row],[Status]]="PU-WC",0,IF(Table_ExternalData_14[[#This Row],[Potensi WO]]=1,Table_ExternalData_14[[#This Row],[CWO Amt]],0))) -> 11.239405 | DH13: =VLOOKUP(Table_ExternalData_14[[#This Row],[BranchID]],KC!$A:$K,5,0) -> 4W | DI13: =VLOOKUP(Table_ExternalData_14[[#This Row],[BranchID]],KC!$A:$K,8,0) -> 07. Sumbagsel | DJ13: =VLOOKUP(Table_ExternalData_14[[#This Row],[BranchID]],KC!$A:$K,9,0) -> PALEMBANG | DK13: =IF(Table_ExternalData_14[[#This Row],[Tanggal_Sukses]]=" ",Table_ExternalData_14[[#This Row],[Tanggal_Sukses]],VLOOKUP(Table_ExternalData_14[[#This Row],[ContractID]],Bantuan!$A:$C,2,0)) -> 0 | DL13: =IF(Table_ExternalData_14[[#This Row],[Keterangan_Sukses]]=" ",Table_ExternalData_14[[#This Row],[Keterangan_Sukses]],VLOOKUP(Table_ExternalData_14[[#This Row],[ContractID]],Bantuan!$A:$C,3,0)) -> 0
A14: 1532 | B14: PALEMBANG | C14: 46142 | D14: 45981 | E14: 44679 | F14: 1532C20210500001 | G14: 1532220000037 | H14: DRS MIRHAN | I14: RIGANGAN III RT 000 RW 000 Kel.RIGANGAN III Kec. KELAM TENGAH Kota KAUR 38956 | J14: 38956 | L14: 38956 | M14: RIGANGAN III | N14: KELAM TENGAH | O14: KAUR | P14: 15320000 | Q14: Bengkulu | T14: 7804**** | U14: 7804**** | V14: 08127******* | W14: MOBIL Baru | X14: SUZUKI | Y14: BALENO | Z14: NEW BALENO MT | AA14: MBHEWB52SMG738211 | AB14: K14BN4188857 | AC14: BD 1449 WB | AD14: 133000000 | AE14: 1.120741e+08 | AF14: 110200000 | AG14: 22800000 | AH14: 50512600 | AI14: 0 | AJ14: 3800000 | AK14: 161 | AL14: 6 | AM14: 42 | AN14: 76 | AO14: 06.151-180 | AP14: 06.151-180 | AQ14: 03.RO | BF14: Coll-Head | BG14: Collectible | BH14: 7 | BI14: 26600000 | BN14: 46173 | BO14: 1 | BP14: 46149 | BQ14: Coll Harian | BR14: 138 | BS14: 46011 | BT14: 129200000 | BU14: 3800000 | BV14: 0 | BW14: 0 | BX14: 0 | BY14: 1 | BZ14: 1 | CA14: 3800000 | CB14: 3800000 | CD14: 0 | CF14: 0 | CH14: 0 | CJ14: 0 | CL14: 0 | CM14: 46149 | CN14: 4W | CO14: 1.120741e+08 | CP14: 0 | CQ14: 0 | CR14: 46144 | CS14: RB | CT14: 1.120741e+08 | CU14: PALEMBANG 3 - MBL | CV14: 06. Sumatera Selatan | CW14: 46149 | CX14: Last Month | CY14: =MONTH(Table_ExternalData_14[[#This Row],[RunningReportDate]]) -> 5 | CZ14: =181-Table_ExternalData_14[[#This Row],[DaysOD]] -> 20 | DA14: =IF(Table_ExternalData_14[[#This Row],[Status]]="PU-WC",0,Table_ExternalData_14[[#This Row],[Amount_CWO]]/1000000) -> 112.0741 | DB14: =IF(Table_ExternalData_14[[#This Row],[Status]]="PU-WC",0,IF(Table_ExternalData_14[[#This Row],[Keterangan_Sukses-new]]="RB",1,IF(Table_ExternalData_14[[#This Row],[Keterangan_Sukses-new]]="STAY",1,IF(Table_ExternalData_14[[#This Row],[Keterangan_Sukses-new]]="BTC",1,IF(ISERROR(FIND("SEBELUM",Table_ExternalData_14[[#This Row],[Keterangan_Sukses-new]],1)),0,1))))) -> 1 | DC14: =IF(Table_ExternalData_14[[#This Row],[Status]]="PU-WC",0,IF(Table_ExternalData_14[[#This Row],[Success CWO]]=1,Table_ExternalData_14[[#This Row],[CWO Amt]],0)) -> 112.0741 | DD14: =IF(AND(Table_ExternalData_14[[#This Row],[Status]]="InsuranceClaim",Table_ExternalData_14[[#This Row],[TglTarik]]>0),0,IF(Table_ExternalData_14[[#This Row],[ContractID]]="1547220000067",0,IF(Table_ExternalData_14[[#This Row],[Status]]="PU-WC",0,IF(Table_ExternalData_14[[#This Row],[Tgl WO-in]]<= DAY(Table_ExternalData_14[[#This Row],[Period]]),Table_ExternalData_14[[#This Row],[Amount_WO]]/1000000,0)))) -> 0 | DE14: =DAY(Table_ExternalData_14[[#This Row],[Tanggal_Sukses-new]]) -> 2 | DF14: =IF(Table_ExternalData_14[[#This Row],[Status]]="PU-WC",0,IF(SUM(Table_ExternalData_14[[#This Row],[Success CWO]:[WO-In-Amt]])=0,1,0)) -> 0 | DG14: =IF(AND(Table_ExternalData_14[[#This Row],[Status]]="InsuranceClaim",Table_ExternalData_14[[#This Row],[TglTarik]]>0),0,IF(Table_ExternalData_14[[#This Row],[Status]]="PU-WC",0,IF(Table_ExternalData_14[[#This Row],[Potensi WO]]=1,Table_ExternalData_14[[#This Row],[CWO Amt]],0))) -> 0 | DH14: =VLOOKUP(Table_ExternalData_14[[#This Row],[BranchID]],KC!$A:$K,5,0) -> 4W | DI14: =VLOOKUP(Table_ExternalData_14[[#This Row],[BranchID]],KC!$A:$K,8,0) -> 07. Sumbagsel | DJ14: =VLOOKUP(Table_ExternalData_14[[#This Row],[BranchID]],KC!$A:$K,9,0) -> PALEMBANG | DK14: =IF(Table_ExternalData_14[[#This Row],[Tanggal_Sukses]]=" ",Table_ExternalData_14[[#This Row],[Tanggal_Sukses]],VLOOKUP(Table_ExternalData_14[[#This Row],[ContractID]],Bantuan!$A:$C,2,0)) -> 46144 | DL14: =IF(Table_ExternalData_14[[#This Row],[Keterangan_Sukses]]=" ",Table_ExternalData_14[[#This Row],[Keterangan_Sukses]],VLOOKUP(Table_ExternalData_14[[#This Row],[ContractID]],Bantuan!$A:$C,3,0)) -> RB
